Workbook

Sheet LCOE
A1: LCOE and learning effects calculator v2.2 (2024) | D1: Good comparison of different LCOE methodologies: Foster, J., Wagner, L., & Bratanova, A. (2014). LCOE models: A comparison of the theoretical frameworks and key assumptions. CSIRO. https://www.researchgate.net/publication/264311516_LCOE_models_A_comparison_of_the_theoretical_frameworks_and_key_assumptions
A2: Link to OneDrive version (view only) | D2: Alter ONLY inputs in GREEN CELLS!
A3: Power plant details | D3: LCOE 1 | E3: LCOE 2 | F3: LCOE 3 | G3: LCOE 4 | H3: LCOE 5 | I3: LCOE 6 | J3: LCOE 7 | K3: LCOE 8 | L3: Explanations
C4: Type | D4: Gas Combined Cycle Turbine (CCGT) | E4: Gas Combined Cycle Turbine (CCGT) | F4: Gas Combined Cycle Turbine (CCGT) | G4: Gas Combined Cycle Turbine (CCGT) | H4: Gas Combined Cycle Turbine (CCGT) | I4: Gas Combined Cycle Turbine (CCGT) | J4: Gas Combined Cycle Turbine (CCGT) | K4: Gas Combined Cycle Turbine (CCGT) | L4: Type of power plant
C5: Name | D5: CCGT in Belgium (2020) | E5: CCGT in Belgium (2020) | F5: CCGT in Belgium (2020) | G5: CCGT in Belgium (2020) | H5: CCGT in Belgium (2020) | I5: CCGT in Belgium (2020) | J5: CCGT in Belgium (2020) | K5: CCGT in Belgium (2020) | L5: The name of the calculation. Will be used in the Results.
B6: Currency | C6: Currency used for LCOE calculations | D6: USD | E6: USD | F6: USD | G6: USD | H6: USD | I6: USD | J6: USD | K6: USD | L6: Currency used for calculations. Most international studies use USD.
C7: Price reference year | L7: Reference year to use in currency conversion.
C8: Currency used | D8: USD | E8: USD | F8: USD | G8: USD | H8: USD | I8: USD | J8: USD | K8: USD | L8: Currency used to report the results and in the learning curve calculations
C9: Conversion rate at reference year | D9: 1 | E9: 1 | F9: 1 | G9: 1 | H9: 1 | I9: 1 | J9: 1 | K9: 1 | L9: The conversion rate during reference year, from currency used in calculations to currency used in the results.
B10: Financing | C10: Debt % | D10: 0.9 | E10: 0.9 | F10: 0.9 | G10: 0.9 | H10: 0.9 | I10: 0.9 | J10: 0.9 | K10: 0.9 | L10: How the project is financed? The share of debt of total financing.
C11: Cost of debt (private discount rate) | D11: 0 | E11: 0.03 | F11: 0.05 | G11: 0.07 | H11: 0.08 | I11: 0.1 | J11: 0.12 | K11: 0.14 | L11: The discount rate used for debt; the interest rate that banks will charge the consumer. Also known as the private discount rate (PDR) or opportunity cost of capital
C12: Cost of equity (discount rate) | D12: 0 | E12: 0.03 | F12: 0.05 | G12: 0.07 | H12: 0.08 | I12: 0.1 | J12: 0.12 | K12: 0.14 | L12: The discount rate used for equity. Typically higher than discount rate for debt.
B13: Cost | C13: Construction cost per kW | D13: 1009 | E13: 1009 | F13: 1009 | G13: 1009 | H13: 1009 | I13: 1009 | J13: 1009 | K13: 1009 | L13: Upfront cost of the power plant, per kW of maximum power (electricity if electric of CHP producer, heat if maximum electric power = 0)
B14: Power | C14: Maximum electric power, in MW_e | D14: 500 | E14: 500 | F14: 500 | G14: 500 | H14: 500 | I14: 500 | J14: 500 | K14: 500 | L14: Maximum electricity output of the plant
C15: Maximum heat power, in MW_h | D15: 0 | E15: 0 | F15: 0 | G15: 0 | H15: 0 | I15: 0 | J15: 0 | K15: 0 | L15: Maximum heat output of the plant, for e.g. district heating
B16: Lifetime | C16: Plant lifetime | D16: 30 | E16: 30 | F16: 30 | G16: 30 | H16: 30 | I16: 30 | J16: 30 | K16: 30 | L16: Maximum economical lifetime of the plant. Maximum 100 years.
B17: Build time | C17: Construction period, years | D17: 3 | E17: 3 | F17: 3 | G17: 3 | H17: 3 | I17: 3 | J17: 3 | K17: 3 | L17: Years required to construct the plant. Overnight cost is divided equally to these years and IDC is applied. Set to 1 to obtain Overnight costs.
B18: CF | C18: Capacity factor (settled down) | D18: 0.9 | E18: 0.9 | F18: 0.9 | G18: 0.9 | H18: 0.9 | I18: 0.9 | J18: 0.9 | K18: 0.9 | L18: Capacity factor (also known as load factor) once the plant has completed its testing cycle and operates normally
C19: Capacity factor ramp-up on startup, per year | D19: 0.6 | E19: 0.6 | F19: 0.6 | G19: 0.6 | H19: 0.6 | I19: 0.6 | J19: 0.6 | K19: 0.6 | L19: How rapidly the capacity factor ramps up to settled down rate, improvement per year. Plants start at 50 % of their maximum capacity factor.
B20: OPEX | C20: Fixed OPEX/MW capacity at project start | D20: 40000 | E20: 40000 | F20: 40000 | G20: 40000 | H20: 40000 | I20: 40000 | J20: 40000 | K20: 40000 | L20: Operational expenditure that isn't dependent on the amount of energy generated. If max electric power > 0, the OPEX is calculated from maximum electric power; otherwise from maximum heat power.
C21: Variable OPEX/MWh produced at project start | D21: 0 | E21: 0 | F21: 0 | G21: 0 | H21: 0 | I21: 0 | J21: 0 | K21: 0 | L21: Variable operational costs (costs dependent on amount of energy generated). If max electric power > 0, the OPEX is calculated from electricity output; otherwise from heat output.
C22: OPEX escalator | D22: 0 | E22: 0 | F22: 0 | G22: 0 | H22: 0 | I22: 0 | J22: 0 | K22: 0 | L22: Increase in OPEX per year
B23: Fuel costs | C23: FUELEX/MWh produced at project start | D23: 42.66 | E23: 42.66 | F23: 42.66 | G23: 42.66 | H23: 42.66 | I23: 42.66 | J23: 42.66 | K23: 42.66 | L23: Cost of fuel, per MWh of electricity generated if maximum electric power >0, otherwise per MWh of heat produced
C24: FUELEX escalator | D24: 0 | E24: 0 | F24: 0 | G24: 0 | H24: 0 | I24: 0 | J24: 0 | K24: 0 | L24: Increase in fuel costs per year
C25: Efficiency loss/year | D25: 0 | E25: 0 | F25: 0 | G25: 0 | H25: 0 | I25: 0 | J25: 0 | K25: 0 | L25: Loss of production as the plant ages. Used mostly fro solar PV.
B26: Midlife | C26: Refurbishment year | D26: 101 | E26: 101 | F26: 101 | G26: 101 | H26: 101 | I26: 101 | J26: 101 | K26: 101 | L26: Year when plant is refurbished. Set to 101 or more if no refurbishment needed.
C27: Refurbishment time required, years | D27: 1 | E27: 1 | F27: 1 | G27: 1 | H27: 1 | I27: 1 | J27: 1 | K27: 1 | L27: Time required for refurbishment, in years. Cost of refurbishment is divided equally to these years.
C28: Refurbishment cost, per kW | D28: 0 | E28: 0 | F28: 0 | G28: 0 | H28: 0 | I28: 0 | J28: 0 | K28: 0 | L28: Cost to refurbish the plant, per kW of maximum original capacity (electric if max electric power >0, heat otherwiase)
B29: Emissions | C29: Emission factor, gCO2e/kWh | D29: 313.75 | E29: 313.75 | F29: 313.75 | G29: 313.75 | H29: 313.75 | I29: 313.75 | J29: 313.75 | K29: 313.75 | L29: CO2 equivalent emissions produced per kWh of electricity generated if max electric power >0, otherwise per kWh of heat generated. From e.g. IPCC reports.
C30: Emissions taxed starting from year | D30: 0 | E30: 0 | F30: 0 | G30: 0 | H30: 0 | I30: 0 | J30: 0 | K30: 0 | L30: If emissions are taxed (see below for CO2 prices), when the plant is subject to taxation? Set to "0' for immediately, "101" if never
B31: Taxes | C31: Taxes, per MWh produced | D31: 0 | E31: 0 | F31: 0 | G31: 0 | H31: 0 | I31: 0 | J31: 0 | K31: 0 | L31: Taxes levied per MWh produced, electricity if max electric power >0, heat otherwise. DOES NOT INCLUDE CARBON TAX OR EMISSION TRADING
C32: Waste fee, per MWh produced | D32: 0 | E32: 0 | F32: 0 | G32: 0 | H32: 0 | I32: 0 | J32: 0 | K32: 0 | L32: Waste fees levied per MWh produced, electricity if max electric power >0, heat otherwise
C33: Heat credit, per MWh produced | D33: 30 | E33: 30 | F33: 30 | G33: 30 | H33: 30 | I33: 30 | J33: 30 | K33: 30 | L33: Income from selling a MWh of heat
C34: Outage at year | D34: 101 | E34: 101 | F34: 101 | G34: 101 | H34: 101 | I34: 101 | J34: 101 | K34: 101 | L34: This can be used to introduce a year-long outage. Number denotes the year after startup for outages. Set to "101" for no outages. Outages can also be introduced via Overrides below.
B35: EOL costs | C35: Decommissioning costs, % of initial capital cost | D35: 0.05 | E35: 0.05 | F35: 0.05 | G35: 0.05 | H35: 0.05 | I35: 0.05 | J35: 0.05 | K35: 0.05 | L35: Decommissioning cost as a fraction of initial capital cost (overnight costs)
C36: Decommissioning delay, years | D36: 25 | E36: 1 | F36: 1 | G36: 2 | H36: 2 | I36: 2 | J36: 2 | K36: 2 | L36: Delay after plant is closed, but before decommissioning begins. Influences LCOE due to discount rate. Maximum 25 years
C37: Results reference year/LC start year | D37: 2020 | E37: 2020 | F37: 2020 | G37: 2020 | H37: 2020 | I37: 2020 | J37: 2020 | K37: 2020 | L37: Reference year to use in currency conversion and in LC timeline
C38: Total cost | D38: =IF(D14>0,D13*1000*D14,D13*1000*D15) -> 504500000 | E38: =IF(E14>0,E13*1000*E14,E13*1000*E15) -> 504500000 | F38: =IF(F14>0,F13*1000*F14,F13*1000*F15) -> 504500000 | G38: =IF(G14>0,G13*1000*G14,G13*1000*G15) -> 504500000 | H38: =IF(H14>0,H13*1000*H14,H13*1000*H15) -> 504500000 | I38: =IF(I14>0,I13*1000*I14,I13*1000*I15) -> 504500000 | J38: =IF(J14>0,J13*1000*J14,J13*1000*J15) -> 504500000 | K38: =IF(K14>0,K13*1000*K14,K13*1000*K15) -> 504500000 | L38: DO NOT ALTER. Calculates the total overnight cost (maximum electric power * overnight cost per kW if max electric power >0; otherwise max heat power * overnight cost per kW)
C39: Equity share | D39: =100%-D10 -> 0.1 | E39: =100%-E10 -> 0.1 | F39: =100%-F10 -> 0.1 | G39: =100%-G10 -> 0.1 | H39: =100%-H10 -> 0.1 | I39: =100%-I10 -> 0.1 | J39: =100%-J10 -> 0.1 | K39: =100%-K10 -> 0.1 | L39: DO NOT ALTER. Shows the share of equity, just for completeness' sake
C40: WACC (average discount rate) | D40: =D10*D11+D39*D12 -> 0 | E40: =E10*E11+E39*E12 -> 0.03 | F40: =F10*F11+F39*F12 -> 0.05 | G40: =G10*G11+G39*G12 -> 0.07 | H40: =H10*H11+H39*H12 -> 0.08 | I40: =I10*I11+I39*I12 -> 0.1 | J40: =J10*J11+J39*J12 -> 0.12 | K40: =K10*K11+K39*K12 -> 0.14 | L40: DO NOT ALTER. Shows the weighted average discount rate that is used in calculations
...

Sheet Learning curve parameters
C2: Start year: | D2: =LCOE!D37 -> 2020
C4: Case | D4: LC Case 1 | E4: LC Case 2 | F4: LC Case 3 | G4: LC Case 4 | H4: LC Case 5 | I4: LC Case 6 | J4: LC Case 7 | K4: LC Case 8
C5: LCOE calc | D5: =LCOE!D3 -> LCOE 1 | E5: =LCOE!E3 -> LCOE 2 | F5: =LCOE!F3 -> LCOE 3 | G5: =LCOE!G3 -> LCOE 4 | H5: =LCOE!H3 -> LCOE 5 | I5: =LCOE!I3 -> LCOE 6 | J5: =LCOE!J3 -> LCOE 7 | K5: =LCOE!K3 -> LCOE 8
C6: LCOE name | D6: =LCOE!D5 -> CCGT in Belgium (2020) | E6: =LCOE!E5 -> CCGT in Belgium (2020) | F6: =LCOE!F5 -> CCGT in Belgium (2020) | G6: =LCOE!G5 -> CCGT in Belgium (2020) | H6: =LCOE!H5 -> CCGT in Belgium (2020) | I6: =LCOE!I5 -> CCGT in Belgium (2020) | J6: =LCOE!J5 -> CCGT in Belgium (2020) | K6: =LCOE!K5 -> CCGT in Belgium (2020)
C7: Cumulative production at t=0 | D7: 95782 | E7: 95782 | F7: 95782 | G7: 95782 | H7: 95782 | I7: 95782 | J7: 95782 | K7: 95782
C8: Cumulative production unit | D8: TWh | E8: TWh | F8: TWh | G8: TWh | H8: TWh | I8: TWh | J8: TWh | K8: TWh
D27: Experience exponent ω | M27: Production growth rate
A28: Year | B28: Year | C28: Emission costs, per tCO2e | D28: =D4 -> LC Case 1 | E28: =E4 -> LC Case 2 | F28: =F4 -> LC Case 3 | G28: =G4 -> LC Case 4 | H28: =H4 -> LC Case 5 | I28: =I4 -> LC Case 6 | J28: =J4 -> LC Case 7 | K28: =K4 -> LC Case 8 | M28: =D4 -> LC Case 1 | N28: =E4 -> LC Case 2 | O28: =F4 -> LC Case 3 | P28: =G4 -> LC Case 4 | Q28: =H4 -> LC Case 5 | R28: =I4 -> LC Case 6 | S28: =J4 -> LC Case 7 | T28: =K4 -> LC Case 8
A29: 0 | B29: =A29+D$2 -> 2020 | D29: 0.05 | E29: 0.05 | F29: 0.05 | G29: 0.05 | H29: 0.05 | I29: 0.05 | J29: 0.05 | K29: 0.05 | M29: 0.01 | N29: 0.01 | O29: 0.01 | P29: 0.01 | Q29: 0.01 | R29: 0.01 | S29: 0.01 | T29: 0.01
A30: 1 | B30: =A30+D$2 -> 2021 | D30: 0.05 | E30: 0.05 | F30: 0.05 | G30: 0.05 | H30: 0.05 | I30: 0.05 | J30: 0.05 | K30: 0.05 | M30: 0.01 | N30: 0.01 | O30: 0.01 | P30: 0.01 | Q30: 0.01 | R30: 0.01 | S30: 0.01 | T30: 0.01
A31: 2 | B31: =A31+D$2 -> 2022 | D31: 0.05 | E31: 0.05 | F31: 0.05 | G31: 0.05 | H31: 0.05 | I31: 0.05 | J31: 0.05 | K31: 0.05 | M31: 0.01 | N31: 0.01 | O31: 0.01 | P31: 0.01 | Q31: 0.01 | R31: 0.01 | S31: 0.01 | T31: 0.01
A32: 3 | B32: =A32+D$2 -> 2023 | D32: 0.05 | E32: 0.05 | F32: 0.05 | G32: 0.05 | H32: 0.05 | I32: 0.05 | J32: 0.05 | K32: 0.05 | M32: 0.01 | N32: 0.01 | O32: 0.01 | P32: 0.01 | Q32: 0.01 | R32: 0.01 | S32: 0.01 | T32: 0.01
A33: 4 | B33: =A33+D$2 -> 2024 | D33: 0.05 | E33: 0.05 | F33: 0.05 | G33: 0.05 | H33: 0.05 | I33: 0.05 | J33: 0.05 | K33: 0.05 | M33: 0.01 | N33: 0.01 | O33: 0.01 | P33: 0.01 | Q33: 0.01 | R33: 0.01 | S33: 0.01 | T33: 0.01
A34: 5 | B34: =A34+D$2 -> 2025 | D34: 0.05 | E34: 0.05 | F34: 0.05 | G34: 0.05 | H34: 0.05 | I34: 0.05 | J34: 0.05 | K34: 0.05 | M34: 0.01 | N34: 0.01 | O34: 0.01 | P34: 0.01 | Q34: 0.01 | R34: 0.01 | S34: 0.01 | T34: 0.01
A35: 6 | B35: =A35+D$2 -> 2026 | D35: 0.05 | E35: 0.05 | F35: 0.05 | G35: 0.05 | H35: 0.05 | I35: 0.05 | J35: 0.05 | K35: 0.05 | M35: 0.01 | N35: 0.01 | O35: 0.01 | P35: 0.01 | Q35: 0.01 | R35: 0.01 | S35: 0.01 | T35: 0.01
A36: 7 | B36: =A36+D$2 -> 2027 | D36: 0.05 | E36: 0.05 | F36: 0.05 | G36: 0.05 | H36: 0.05 | I36: 0.05 | J36: 0.05 | K36: 0.05 | M36: 0.01 | N36: 0.01 | O36: 0.01 | P36: 0.01 | Q36: 0.01 | R36: 0.01 | S36: 0.01 | T36: 0.01
A37: 8 | B37: =A37+D$2 -> 2028 | D37: 0.05 | E37: 0.05 | F37: 0.05 | G37: 0.05 | H37: 0.05 | I37: 0.05 | J37: 0.05 | K37: 0.05 | M37: 0.01 | N37: 0.01 | O37: 0.01 | P37: 0.01 | Q37: 0.01 | R37: 0.01 | S37: 0.01 | T37: 0.01
A38: 9 | B38: =A38+D$2 -> 2029 | D38: 0.05 | E38: 0.05 | F38: 0.05 | G38: 0.05 | H38: 0.05 | I38: 0.05 | J38: 0.05 | K38: 0.05 | M38: 0.01 | N38: 0.01 | O38: 0.01 | P38: 0.01 | Q38: 0.01 | R38: 0.01 | S38: 0.01 | T38: 0.01
A39: 10 | B39: =A39+D$2 -> 2030 | D39: 0.05 | E39: 0.05 | F39: 0.05 | G39: 0.05 | H39: 0.05 | I39: 0.05 | J39: 0.05 | K39: 0.05 | M39: 0.01 | N39: 0.01 | O39: 0.01 | P39: 0.01 | Q39: 0.01 | R39: 0.01 | S39: 0.01 | T39: 0.01
A40: 11 | B40: =A40+D$2 -> 2031 | D40: 0.05 | E40: 0.05 | F40: 0.05 | G40: 0.05 | H40: 0.05 | I40: 0.05 | J40: 0.05 | K40: 0.05 | M40: 0.01 | N40: 0.01 | O40: 0.01 | P40: 0.01 | Q40: 0.01 | R40: 0.01 | S40: 0.01 | T40: 0.01
... A129: 100 | B129: =A129+D$2 -> 2120 | D129: 0.05 | E129: 0.05 | F129: 0.05 | G129: 0.05 | H129: 0.05 | I129: 0.05 | J129: 0.05 | K129: 0.05 | M129: 0.01 | N129: 0.01 | O129: 0.01 | P129: 0.01 | Q129: 0.01 | R129: 0.01 | S129: 0.01 | T129: 0.01

Sheet Results
B6: Calculation | C6: =LCOE!D3 -> LCOE 1 | D6: =LCOE!E3 -> LCOE 2 | E6: =LCOE!F3 -> LCOE 3 | F6: =LCOE!G3 -> LCOE 4 | G6: =LCOE!H3 -> LCOE 5 | H6: =LCOE!I3 -> LCOE 6 | I6: =LCOE!J3 -> LCOE 7 | J6: =LCOE!K3 -> LCOE 8
B7: Name | C7: =LCOE!D5 -> CCGT in Belgium (2020) | D7: =LCOE!E5 -> CCGT in Belgium (2020) | E7: =LCOE!F5 -> CCGT in Belgium (2020) | F7: =LCOE!G5 -> CCGT in Belgium (2020) | G7: =LCOE!H5 -> CCGT in Belgium (2020) | H7: =LCOE!I5 -> CCGT in Belgium (2020) | I7: =LCOE!J5 -> CCGT in Belgium (2020) | J7: =LCOE!K5 -> CCGT in Belgium (2020)
B8: =LCOE!C6 -> Currency used for LCOE calculations
A10: LCOE
B11: =LCOE!C13 -> Construction cost per kW | C11: =LCOE!D13 -> 1009 | D11: =LCOE!E13 -> 1009 | E11: =LCOE!F13 -> 1009 | F11: =LCOE!G13 -> 1009 | G11: =LCOE!H13 -> 1009 | H11: =LCOE!I13 -> 1009 | I11: =LCOE!J13 -> 1009 | J11: =LCOE!K13 -> 1009
B12: =LCOE!C14 -> Maximum electric power, in MW_e | C12: =LCOE!D14 -> 500 | D12: =LCOE!E14 -> 500 | E12: =LCOE!F14 -> 500 | F12: =LCOE!G14 -> 500 | G12: =LCOE!H14 -> 500 | H12: =LCOE!I14 -> 500 | I12: =LCOE!J14 -> 500 | J12: =LCOE!K14 -> 500
B13: =LCOE!C15 -> Maximum heat power, in MW_h | C13: =LCOE!D15 -> 0 | D13: =LCOE!E15 -> 0 | E13: =LCOE!F15 -> 0 | F13: =LCOE!G15 -> 0 | G13: =LCOE!H15 -> 0 | H13: =LCOE!I15 -> 0 | I13: =LCOE!J15 -> 0 | J13: =LCOE!K15 -> 0
B14: =LCOE!C52 -> Heat credit (for CHP plants) | C14: =LCOE!D52 -> 0 | D14: =LCOE!E52 -> 0 | E14: =LCOE!F52 -> 0 | F14: =LCOE!G52 -> 0 | G14: =LCOE!H52 -> 0 | H14: =LCOE!I52 -> 0 | I14: =LCOE!J52 -> 0 | J14: =LCOE!K52 -> 0
C15: =LCOE!D45 -> USD/MWh | D15: =LCOE!E45 -> USD/MWh | E15: =LCOE!F45 -> USD/MWh | F15: =LCOE!G45 -> USD/MWh | G15: =LCOE!H45 -> USD/MWh | H15: =LCOE!I45 -> USD/MWh | I15: =LCOE!J45 -> USD/MWh | J15: =LCOE!K45 -> USD/MWh
B16: =LCOE!C46 -> LCOE (LCOHeat for pure heat plants) | C16: =LCOE!D46 -> 71.201772 | D16: =LCOE!E46 -> 64.075543 | E16: =LCOE!F46 -> 66.035232 | F16: =LCOE!G46 -> 68.258027 | G16: =LCOE!H46 -> 69.460824 | H16: =LCOE!I46 -> 72.022033 | I16: =LCOE!J46 -> 74.762467 | J16: =LCOE!K46 -> 77.652831
B17: =LCOE!C47 -> Of which: Capital costs | C17: =LCOE!D47 -> 13.938494 | D17: =LCOE!E47 -> 6.7525504 | E17: =LCOE!F47 -> 8.6657769 | F17: =LCOE!G47 -> 10.838019 | G17: =LCOE!H47 -> 12.014364 | H17: =LCOE!I47 -> 14.520992 | I17: =LCOE!J47 -> 17.205402 | J17: =LCOE!K47 -> 20.039072
B18: =LCOE!C48 -> O&M | C18: =LCOE!D48 -> 5.1907778 | D18: =LCOE!E48 -> 5.250493 | E18: =LCOE!F48 -> 5.2969555 | F18: =LCOE!G48 -> 5.3475079 | G18: =LCOE!H48 -> 5.3739602 | H18: =LCOE!I48 -> 5.4285401 | I18: =LCOE!J48 -> 5.4845655 | J18: =LCOE!K48 -> 5.5412584
B19: =LCOE!C49 -> Fuel | C19: =LCOE!D49 -> 42.66 | D19: =LCOE!E49 -> 42.66 | E19: =LCOE!F49 -> 42.66 | F19: =LCOE!G49 -> 42.66 | G19: =LCOE!H49 -> 42.66 | H19: =LCOE!I49 -> 42.66 | I19: =LCOE!J49 -> 42.66 | J19: =LCOE!K49 -> 42.66
B20: =LCOE!C50 -> Taxes and fees | C20: =LCOE!D50 -> 0 | D20: =LCOE!E50 -> 0 | E20: =LCOE!F50 -> 0 | F20: =LCOE!G50 -> 0 | G20: =LCOE!H50 -> 0 | H20: =LCOE!I50 -> 0 | I20: =LCOE!J50 -> 0 | J20: =LCOE!K50 -> 0
B21: =LCOE!C51 -> Emission costs | C21: =LCOE!D51 -> 9.4125 | D21: =LCOE!E51 -> 9.4125 | E21: =LCOE!F51 -> 9.4125 | F21: =LCOE!G51 -> 9.4125 | G21: =LCOE!H51 -> 9.4125 | H21: =LCOE!I51 -> 9.4125 | I21: =LCOE!J51 -> 9.4125 | J21: =LCOE!K51 -> 9.4125
B22: =LCOE!C52 -> Heat credit (for CHP plants) | C22: =LCOE!D52 -> 0 | D22: =LCOE!E52 -> 0 | E22: =LCOE!F52 -> 0 | F22: =LCOE!G52 -> 0 | G22: =LCOE!H52 -> 0 | H22: =LCOE!I52 -> 0 | I22: =LCOE!J52 -> 0 | J22: =LCOE!K52 -> 0
B23: =LCOE!C53 -> WACC average over lifetime | C23: =LCOE!D53 -> 0 | D23: =LCOE!E53 -> 0.03 | E23: =LCOE!F53 -> 0.05 | F23: =LCOE!G53 -> 0.07 | G23: =LCOE!H53 -> 0.08 | H23: =LCOE!I53 -> 0.1 | I23: =LCOE!J53 -> 0.12 | J23: =LCOE!K53 -> 0.14
B24: =LCOE!C54 -> Plant type | C24: =LCOE!D54 -> Electric only | D24: =LCOE!E54 -> Electric only | E24: =LCOE!F54 -> Electric only | F24: =LCOE!G54 -> Electric only | G24: =LCOE!H54 -> Electric only | H24: =LCOE!I54 -> Electric only | I24: =LCOE!J54 -> Electric only | J24: =LCOE!K54 -> Electric only
A26: Learning curve
B28: ='Learning curve calcs'!B21 -> Case | C28: ='Learning curve calcs'!C21 -> LC Case 1 | D28: ='Learning curve calcs'!D21 -> LC Case 2 | E28: ='Learning curve calcs'!E21 -> LC Case 3 | F28: ='Learning curve calcs'!F21 -> LC Case 4 | G28: ='Learning curve calcs'!G21 -> LC Case 5 | H28: ='Learning curve calcs'!H21 -> LC Case 6 | I28: ='Learning curve calcs'!I21 -> LC Case 7 | J28: ='Learning curve calcs'!J21 -> LC Case 8
B29: ='Learning curve calcs'!B22 -> LCOE calc | C29: ='Learning curve calcs'!C22 -> LCOE 1 | D29: ='Learning curve calcs'!D22 -> LCOE 2 | E29: ='Learning curve calcs'!E22 -> LCOE 3 | F29: ='Learning curve calcs'!F22 -> LCOE 4 | G29: ='Learning curve calcs'!G22 -> LCOE 5 | H29: ='Learning curve calcs'!H22 -> LCOE 6 | I29: ='Learning curve calcs'!I22 -> LCOE 7 | J29: ='Learning curve calcs'!J22 -> LCOE 8
B30: ='Learning curve calcs'!B23 -> Name | C30: ='Learning curve calcs'!C23 -> CCGT in Belgium (2020) | D30: ='Learning curve calcs'!D23 -> CCGT in Belgium (2020) | E30: ='Learning curve calcs'!E23 -> CCGT in Belgium (2020) | F30: ='Learning curve calcs'!F23 -> CCGT in Belgium (2020) | G30: ='Learning curve calcs'!G23 -> CCGT in Belgium (2020) | H30: ='Learning curve calcs'!H23 -> CCGT in Belgium (2020) | I30: ='Learning curve calcs'!I23 -> CCGT in Belgium (2020) | J30: ='Learning curve calcs'!J23 -> CCGT in Belgium (2020)
C32: ='Learning curve calcs'!C24 -> USD/MWh | D32: ='Learning curve calcs'!D24 -> USD/MWh | E32: ='Learning curve calcs'!E24 -> USD/MWh | F32: ='Learning curve calcs'!F24 -> USD/MWh | G32: ='Learning curve calcs'!G24 -> USD/MWh | H32: ='Learning curve calcs'!H24 -> USD/MWh | I32: ='Learning curve calcs'!I24 -> USD/MWh | J32: ='Learning curve calcs'!J24 -> USD/MWh
B33: ='Learning curve calcs'!B24 -> Year | C33: =_xlfn.CONCAT(C30,", WACC ",100*ROUND(C14,2)," %, ",C28) -> CCGT in Belgium (2020), WACC 0 %, LC Case 1 | D33: =_xlfn.CONCAT(D30,", WACC ",100*ROUND(D14,2)," %, ",D28) -> CCGT in Belgium (2020), WACC 0 %, LC Case 2 | E33: =_xlfn.CONCAT(E30,", WACC ",100*ROUND(E14,2)," %, ",E28) -> CCGT in Belgium (2020), WACC 0 %, LC Case 3 | F33: =_xlfn.CONCAT(F30,", WACC ",100*ROUND(F14,2)," %, ",F28) -> CCGT in Belgium (2020), WACC 0 %, LC Case 4 | G33: =_xlfn.CONCAT(G30,", WACC ",100*ROUND(G14,2)," %, ",G28) -> CCGT in Belgium (2020), WACC 0 %, LC Case 5 | H33: =_xlfn.CONCAT(H30,", WACC ",100*ROUND(H14,2)," %, ",H28) -> CCGT in Belgium (2020), WACC 0 %, LC Case 6 | I33: =_xlfn.CONCAT(I30,", WACC ",100*ROUND(I14,2)," %, ",I28) -> CCGT in Belgium (2020), WACC 0 %, LC Case 7 | J33: =_xlfn.CONCAT(J30,", WACC ",100*ROUND(J14,2)," %, ",J28) -> CCGT in Belgium (2020), WACC 0 %, LC Case 8
B34: ='Learning curve calcs'!B25 -> 2020 | C34: ='Learning curve calcs'!C25 -> 71.201772 | D34: ='Learning curve calcs'!D25 -> 64.075543 | E34: ='Learning curve calcs'!E25 -> 66.035232 | F34: ='Learning curve calcs'!F25 -> 68.258027 | G34: ='Learning curve calcs'!G25 -> 69.460824 | H34: ='Learning curve calcs'!H25 -> 72.022033 | I34: ='Learning curve calcs'!I25 -> 74.762467 | J34: ='Learning curve calcs'!J25 -> 77.652831
B35: ='Learning curve calcs'!B26 -> 2021 | C35: ='Learning curve calcs'!C26 -> 71.206621 | D35: ='Learning curve calcs'!D26 -> 64.080392 | E35: ='Learning curve calcs'!E26 -> 66.040081 | F35: ='Learning curve calcs'!F26 -> 68.262876 | G35: ='Learning curve calcs'!G26 -> 69.465672 | H35: ='Learning curve calcs'!H26 -> 72.026881 | I35: ='Learning curve calcs'!I26 -> 74.767316 | J35: ='Learning curve calcs'!J26 -> 77.65768
B36: ='Learning curve calcs'!B27 -> 2022 | C36: ='Learning curve calcs'!C27 -> 71.211469 | D36: ='Learning curve calcs'!D27 -> 64.085241 | E36: ='Learning curve calcs'!E27 -> 66.04493 | F36: ='Learning curve calcs'!F27 -> 68.267724 | G36: ='Learning curve calcs'!G27 -> 69.470521 | H36: ='Learning curve calcs'!H27 -> 72.03173 | I36: ='Learning curve calcs'!I27 -> 74.772165 | J36: ='Learning curve calcs'!J27 -> 77.662528
B37: ='Learning curve calcs'!B28 -> 2023 | C37: ='Learning curve calcs'!C28 -> 71.216318 | D37: ='Learning curve calcs'!D28 -> 64.090089 | E37: ='Learning curve calcs'!E28 -> 66.049778 | F37: ='Learning curve calcs'!F28 -> 68.272573 | G37: ='Learning curve calcs'!G28 -> 69.47537 | H37: ='Learning curve calcs'!H28 -> 72.036578 | I37: ='Learning curve calcs'!I28 -> 74.777013 | J37: ='Learning curve calcs'!J28 -> 77.667377
B38: ='Learning curve calcs'!B29 -> 2024 | C38: ='Learning curve calcs'!C29 -> 71.221167 | D38: ='Learning curve calcs'!D29 -> 64.094938 | E38: ='Learning curve calcs'!E29 -> 66.054627 | F38: ='Learning curve calcs'!F29 -> 68.277422 | G38: ='Learning curve calcs'!G29 -> 69.480218 | H38: ='Learning curve calcs'!H29 -> 72.041427 | I38: ='Learning curve calcs'!I29 -> 74.781862 | J38: ='Learning curve calcs'!J29 -> 77.672225
B39: ='Learning curve calcs'!B30 -> 2025 | C39: ='Learning curve calcs'!C30 -> 71.226015 | D39: ='Learning curve calcs'!D30 -> 64.099787 | E39: ='Learning curve calcs'!E30 -> 66.059476 | F39: ='Learning curve calcs'!F30 -> 68.28227 | G39: ='Learning curve calcs'!G30 -> 69.485067 | H39: ='Learning curve calcs'!H30 -> 72.046276 | I39: ='Learning curve calcs'!I30 -> 74.786711 | J39: ='Learning curve calcs'!J30 -> 77.677074
B40: ='Learning curve calcs'!B31 -> 2026 | C40: ='Learning curve calcs'!C31 -> 71.230864 | D40: ='Learning curve calcs'!D31 -> 64.104635 | E40: ='Learning curve calcs'!E31 -> 66.064324 | F40: ='Learning curve calcs'!F31 -> 68.287119 | G40: ='Learning curve calcs'!G31 -> 69.489916 | H40: ='Learning curve calcs'!H31 -> 72.051124 | I40: ='Learning curve calcs'!I31 -> 74.791559 | J40: ='Learning curve calcs'!J31 -> 77.681923
B41: ='Learning curve calcs'!B32 -> 2027 | C41: ='Learning curve calcs'!C32 -> 71.235713 | D41: ='Learning curve calcs'!D32 -> 64.109484 | E41: ='Learning curve calcs'!E32 -> 66.069173 | F41: ='Learning curve calcs'!F32 -> 68.291968 | G41: ='Learning curve calcs'!G32 -> 69.494764 | H41: ='Learning curve calcs'!H32 -> 72.055973 | I41: ='Learning curve calcs'!I32 -> 74.796408 | J41: ='Learning curve calcs'!J32 -> 77.686771
B42: ='Learning curve calcs'!B33 -> 2028 | C42: ='Learning curve calcs'!C33 -> 71.240561 | D42: ='Learning curve calcs'!D33 -> 64.114333 | E42: ='Learning curve calcs'!E33 -> 66.074022 | F42: ='Learning curve calcs'!F33 -> 68.296816 | G42: ='Learning curve calcs'!G33 -> 69.499613 | H42: ='Learning curve calcs'!H33 -> 72.060822 | I42: ='Learning curve calcs'!I33 -> 74.801257 | J42: ='Learning curve calcs'!J33 -> 77.69162
B43: ='Learning curve calcs'!B34 -> 2029 | C43: ='Learning curve calcs'!C34 -> 71.24541 | D43: ='Learning curve calcs'!D34 -> 64.119181 | E43: ='Learning curve calcs'!E34 -> 66.07887 | F43: ='Learning curve calcs'!F34 -> 68.301665 | G43: ='Learning curve calcs'!G34 -> 69.504462 | H43: ='Learning curve calcs'!H34 -> 72.06567 | I43: ='Learning curve calcs'!I34 -> 74.806105 | J43: ='Learning curve calcs'!J34 -> 77.696469
B44: ='Learning curve calcs'!B35 -> 2030 | C44: ='Learning curve calcs'!C35 -> 71.250259 | D44: ='Learning curve calcs'!D35 -> 64.12403 | E44: ='Learning curve calcs'!E35 -> 66.083719 | F44: ='Learning curve calcs'!F35 -> 68.306514 | G44: ='Learning curve calcs'!G35 -> 69.50931 | H44: ='Learning curve calcs'!H35 -> 72.070519 | I44: ='Learning curve calcs'!I35 -> 74.810954 | J44: ='Learning curve calcs'!J35 -> 77.701317
B45: ='Learning curve calcs'!B36 -> 2031 | C45: ='Learning curve calcs'!C36 -> 71.255107 | D45: ='Learning curve calcs'!D36 -> 64.128879 | E45: ='Learning curve calcs'!E36 -> 66.088568 | F45: ='Learning curve calcs'!F36 -> 68.311362 | G45: ='Learning curve calcs'!G36 -> 69.514159 | H45: ='Learning curve calcs'!H36 -> 72.075368 | I45: ='Learning curve calcs'!I36 -> 74.815803 | J45: ='Learning curve calcs'!J36 -> 77.706166
... B114: ='Learning curve calcs'!B105 -> 2100 | C114: ='Learning curve calcs'!C105 -> 71.589665 | D114: ='Learning curve calcs'!D105 -> 64.463436 | E114: ='Learning curve calcs'!E105 -> 66.423125 | F114: ='Learning curve calcs'!F105 -> 68.64592 | G114: ='Learning curve calcs'!G105 -> 69.848717 | H114: ='Learning curve calcs'!H105 -> 72.409925 | I114: ='Learning curve calcs'!I105 -> 75.15036 | J114: ='Learning curve calcs'!J105 -> 78.040724

Sheet Examples
A4: Power plants
B5: Explanation | C5: Westinghouse winning bid for 3+3 reactors in Poland, 2022 | D5: EDF bid for 4 reactors in Poland, 2022 | E5: CCGT gas turbine in Belgium, 2020, from IEA 2020
B6: Sources | C6: Construction costs from Deutsche Welle via Helsingin Sanomat, 1.2.2023. | D6: Construction costs from Deutsche Welle via Helsingin Sanomat, 1.2.2023 | E6: IEA (2020) Projected Costs of Generating Electricity, pp. 50-57. Converted to EUR ( 1 USD = 0,951 EUR)
J7: 2022
B8: =LCOE!C4 -> Type | C8: Nuclear | D8: Nuclear | E8: Gas Combined Cycle Turbine (CCGT) | J8: Sanmen 1 | K8: 91.3
B9: =LCOE!C5 -> Name | C9: Polish AP1000 bid (2022) | D9: Polish EPR bid (2022) | E9: CCGT in Belgium (2020) | J9: Sanmen 2 | K9: 90.5
B10: =LCOE!C6 -> Currency used for LCOE calculations | C10: EUR | D10: EUR | E10: EUR | J10: 3
B11: =LCOE!C7 -> Price reference year
B12: =LCOE!C8 -> Currency used | C12: EUR | D12: EUR | E12: EUR
B13: =LCOE!C9 -> Conversion rate at reference year | C13: 1 | D13: 1 | E13: 1
B14: =LCOE!C10 -> Debt % | C14: 0.9 | D14: 0.9 | E14: 0.9
B15: =LCOE!C11 -> Cost of debt (private discount rate) | C15: 0.05 | D15: 0.05 | E15: 0.05
B16: =LCOE!C12 -> Cost of equity (discount rate) | C16: 0.05 | D16: 0.05 | E16: 0.05
B17: =LCOE!C13 -> Construction cost per kW | C17: 4441.17 | D17: 4755 | E17: 960
B18: =LCOE!C14 -> Maximum electric power, in MW_e | C18: 1117 | D18: 1650 | E18: 500
B19: =LCOE!C15 -> Maximum heat power, in MW_h | C19: 0 | D19: 0 | E19: 0
B20: =LCOE!C16 -> Plant lifetime | C20: 60 | D20: 60 | E20: 30
B21: =LCOE!C17 -> Construction period, years | C21: 7 | D21: 7 | E21: 3
B22: =LCOE!C18 -> Capacity factor (settled down) | C22: 0.9 | D22: 0.9 | E22: 0.85
B23: =LCOE!C19 -> Capacity factor ramp-up on startup, per year | C23: 0.6 | D23: 0.6 | E23: 1
B24: =LCOE!C20 -> Fixed OPEX/MW capacity at project start | C24: 80835 | D24: 9034.5
B25: =LCOE!C21 -> Variable OPEX/MWh produced at project start | C25: 1426 | D25: 6.55
B26: =LCOE!C22 -> OPEX escalator | C26: 0 | D26: 0
B27: =LCOE!C23 -> FUELEX/MWh produced at project start | C27: 8.87 | D27: 8.87
B28: =LCOE!C24 -> FUELEX escalator | C28: 0 | D28: 0
B29: =LCOE!C25 -> Efficiency loss/year | C29: 0 | D29: 0
B30: =LCOE!C26 -> Refurbishment year | C30: 40 | D30: 40
B31: =LCOE!C27 -> Refurbishment time required, years | C31: 1 | D31: 1
B32: =LCOE!C28 -> Refurbishment cost, per kW | C32: 500 | D32: 500
B33: =LCOE!C29 -> Emission factor, gCO2e/kWh | C33: 12 | D33: 12 | E33: 313.75
B34: =LCOE!C30 -> Emissions taxed starting from year | C34: 101 | D34: 101
B35: =LCOE!C31 -> Taxes, per MWh produced | C35: 0 | D35: 0
B36: =LCOE!C32 -> Waste fee, per MWh produced | C36: 1 | D36: 1
B37: =LCOE!C33 -> Heat credit, per MWh produced | C37: 30 | D37: 30 | E37: 0
B38: =LCOE!C34 -> Outage at year | C38: 101 | D38: 101 | E38: 101
B39: =LCOE!C35 -> Decommissioning costs, % of initial capital cost | C39: 0.15 | D39: 0.15 | E39: 0.05
B40: =LCOE!C36 -> Decommissioning delay, years | C40: 10 | D40: 10 | E40: 2

Sheet LCOE 1
B2: Parameter recap (not used in calcs) | C2: =LCOE!D3 -> LCOE 1 | F2: RESULTS | G2: =C4 -> USD | I2: =C6 -> USD
B3: =LCOE!C5 -> Name | C3: =LCOE!D5 -> CCGT in Belgium (2020) | F3: =LCOE!C46 -> LCOE (LCOHeat for pure heat plants) | G3: =SUM(AH45:AM170)/SUM(AN45:AN170) -> 71.201772 | H3: =_xlfn.CONCAT(C$4,"/MWh") -> USD/MWh | I3: =G3*C$7 -> 71.201772 | J3: =_xlfn.CONCAT(C$6,"/MWh") -> USD/MWh
B4: =LCOE!C6 -> Currency used for LCOE calculations | C4: =LCOE!D6 -> USD | F4: =LCOE!C47 -> Of which: Capital costs | G4: =SUM(AH45:AH170)/SUM(AN45:AN170) -> 13.938494 | H4: =_xlfn.CONCAT(C$4,"/MWh") -> USD/MWh | I4: =G4*C$7 -> 13.938494 | J4: =_xlfn.CONCAT(C$6,"/MWh") -> USD/MWh
B5: =LCOE!C7 -> Price reference year | C5: =LCOE!D7 -> 0 | F5: =LCOE!C48 -> O&M | G5: =SUM(AI45:AI170)/SUM(AN45:AN170) -> 5.1907778 | H5: =_xlfn.CONCAT(C$4,"/MWh") -> USD/MWh | I5: =G5*C$7 -> 5.1907778 | J5: =_xlfn.CONCAT(C$6,"/MWh") -> USD/MWh
B6: =LCOE!C8 -> Currency used | C6: =LCOE!D8 -> USD | F6: =LCOE!C49 -> Fuel | G6: =SUM(AJ45:AJ170)/SUM(AN45:AN170) -> 42.66 | H6: =_xlfn.CONCAT(C$4,"/MWh") -> USD/MWh | I6: =G6*C$7 -> 42.66 | J6: =_xlfn.CONCAT(C$6,"/MWh") -> USD/MWh
B7: =LCOE!C9 -> Conversion rate at reference year | C7: =LCOE!D9 -> 1 | F7: =LCOE!C50 -> Taxes and fees | G7: =SUM(AK45:AK170)/SUM(AN45:AN170) -> 0 | H7: =_xlfn.CONCAT(C$4,"/MWh") -> USD/MWh | I7: =G7*C$7 -> 0 | J7: =_xlfn.CONCAT(C$6,"/MWh") -> USD/MWh
B8: =LCOE!C10 -> Debt % | C8: =LCOE!D10 -> 0.9 | F8: =LCOE!C51 -> Emission costs | G8: =SUM(AL45:AL170)/SUM(AN45:AN170) -> 9.4125 | H8: =_xlfn.CONCAT(C$4,"/MWh") -> USD/MWh | I8: =G8*C$7 -> 9.4125 | J8: =_xlfn.CONCAT(C$6,"/MWh") -> USD/MWh
B9: =LCOE!C11 -> Cost of debt (private discount rate) | C9: =LCOE!D11 -> 0 | F9: =LCOE!C52 -> Heat credit (for CHP plants) | G9: =IF(C15>0,SUM(AM45:AM170)/SUM(AN45:AN170),0) -> 0 | H9: =_xlfn.CONCAT(C$4,"/MWh") -> USD/MWh | I9: =G9*C$7 -> 0 | J9: =_xlfn.CONCAT(C$6,"/MWh") -> USD/MWh
B10: =LCOE!C12 -> Cost of equity (discount rate) | C10: =LCOE!D12 -> 0 | F10: =LCOE!C53 -> WACC average over lifetime | G10: =AVERAGE(AF70:AF170) -> 0 | I10: =G10 -> 0
B11: =LCOE!C13 -> Construction cost per kW | C11: =LCOE!D13 -> 1009 | F11: =LCOE!C54 -> Plant type | G11: =IF(AND(LCOE!D$14>0,LCOE!D$15=0),"Electric only",IF(AND(LCOE!D$14>0,LCOE!D$15>0),"CHP",IF(AND(LCOE!D$14=0,LCOE!D$15>0),"Heat only","Error: no generation"))) -> Electric only | I11: =G11 -> Electric only
B12: =LCOE!C14 -> Maximum electric power, in MW_e | C12: =LCOE!D14 -> 500
B13: =LCOE!C15 -> Maximum heat power, in MW_h | C13: =LCOE!D15 -> 0
B14: =LCOE!C16 -> Plant lifetime | C14: =LCOE!D16 -> 30
B15: =LCOE!C17 -> Construction period, years | C15: =LCOE!D17 -> 3
B16: =LCOE!C18 -> Capacity factor (settled down) | C16: =LCOE!D18 -> 0.9
B17: =LCOE!C19 -> Capacity factor ramp-up on startup, per year | C17: =LCOE!D19 -> 0.6
B18: =LCOE!C20 -> Fixed OPEX/MW capacity at project start | C18: =LCOE!D20 -> 40000
B19: =LCOE!C21 -> Variable OPEX/MWh produced at project start | C19: =LCOE!D21 -> 0
B20: =LCOE!C22 -> OPEX escalator | C20: =LCOE!D22 -> 0
B21: =LCOE!C23 -> FUELEX/MWh produced at project start | C21: =LCOE!D23 -> 42.66
B22: =LCOE!C24 -> FUELEX escalator | C22: =LCOE!D24 -> 0
B23: =LCOE!C25 -> Efficiency loss/year | C23: =LCOE!D25 -> 0
... B41: =LCOE!C43 -> Overrides | C41: =LCOE!D43 -> OVERRIDES CLEAR
Z43: SUMMARY OF COSTS
A44: Year (t) | B44: CAPEXconstr | C44: CAPEXrefurb/decom | D44: Lifetime left? | E44: Operational% | F44: Capacity factor | G44: Electricity produced (MWh_e) | H44: Heat produced (MWh_h) | I44: Fixed OPEX | J44: Variable OPEX | K44: OPEX relative to startup | L44: FUELEX | M44: FUELEX relative to startup | N44: Efficiency relative to startup | O44: Total emission factor, gCO2/kWh | P44: % of emissions taxed | Q44: Total emissions, tCO2e | R44: Cost of tCO2e | S44: Cost of emissions levied, E | T44: Tax per MWh produced | U44: Taxes levied | V44: Waste fee per MWh produced | W44: Waste fee levied | X44: Heat credit per MWh_h | Y44: Heat credit total | Z44: Total capital expenditure, I | AA44: Total operation and maintenance expenditure, M | AB44: Total fuel expenditure, F | AC44: Total taxes, T | AD44: Total emission fees, E | AE44: Lifetime expended at start of year | AF44: Discount rate r (IDC when t<0) | AG44: Discount factor (1+r)^t | AH44: I discounted | AI44: M discounted | AJ44: F discounted | AK44: T discounted | AL44: E discounted | AM44: Heat credit, discounted | AN44: Production (MWh), discounted
A45: -25 | B45: =LCOE!C71+IF(A45>=((LCOE!D$17*-1)+1),LCOE!D$38/LCOE!D$17,0) -> 0 | Z45: =SUM(B45:C45) -> 0 | AA45: =SUM(I45:J45) -> 0 | AB45: =L45 -> 0 | AC45: =SUM(S45:W45) -> 0 | AD45: =S45 -> 0 | AE45: -25 | AF45: =LCOE!E71+LCOE!D$40 -> 0 | AG45: =(1+AF45)^A45 -> 1 | AH45: =Z45/AG45 -> 0 | AI45: =AA45/AG45 -> 0 | AJ45: =AB45/AG45 -> 0 | AK45: =AC45/AG45 -> 0 | AL45: =AD45/AG45 -> 0
A46: -24 | B46: =LCOE!C72+IF(A46>=((LCOE!D$17*-1)+1),LCOE!D$38/LCOE!D$17,0) -> 0 | Z46: =SUM(B46:C46) -> 0 | AA46: =SUM(I46:J46) -> 0 | AB46: =L46 -> 0 | AC46: =SUM(S46:W46) -> 0 | AD46: =S46 -> 0 | AE46: -24 | AF46: =LCOE!E72+LCOE!D$40 -> 0 | AG46: =(1+AF46)^A46 -> 1 | AH46: =Z46/AG46 -> 0 | AI46: =AA46/AG46 -> 0 | AJ46: =AB46/AG46 -> 0 | AK46: =AC46/AG46 -> 0 | AL46: =AD46/AG46 -> 0
A47: -23 | B47: =LCOE!C73+IF(A47>=((LCOE!D$17*-1)+1),LCOE!D$38/LCOE!D$17,0) -> 0 | Z47: =SUM(B47:C47) -> 0 | AA47: =SUM(I47:J47) -> 0 | AB47: =L47 -> 0 | AC47: =SUM(S47:W47) -> 0 | AD47: =S47 -> 0 | AE47: -23 | AF47: =LCOE!E73+LCOE!D$40 -> 0 | AG47: =(1+AF47)^A47 -> 1 | AH47: =Z47/AG47 -> 0 | AI47: =AA47/AG47 -> 0 | AJ47: =AB47/AG47 -> 0 | AK47: =AC47/AG47 -> 0 | AL47: =AD47/AG47 -> 0
A48: -22 | B48: =LCOE!C74+IF(A48>=((LCOE!D$17*-1)+1),LCOE!D$38/LCOE!D$17,0) -> 0 | Z48: =SUM(B48:C48) -> 0 | AA48: =SUM(I48:J48) -> 0 | AB48: =L48 -> 0 | AC48: =SUM(S48:W48) -> 0 | AD48: =S48 -> 0 | AE48: -22 | AF48: =LCOE!E74+LCOE!D$40 -> 0 | AG48: =(1+AF48)^A48 -> 1 | AH48: =Z48/AG48 -> 0 | AI48: =AA48/AG48 -> 0 | AJ48: =AB48/AG48 -> 0 | AK48: =AC48/AG48 -> 0 | AL48: =AD48/AG48 -> 0
A49: -21 | B49: =LCOE!C75+IF(A49>=((LCOE!D$17*-1)+1),LCOE!D$38/LCOE!D$17,0) -> 0 | Z49: =SUM(B49:C49) -> 0 | AA49: =SUM(I49:J49) -> 0 | AB49: =L49 -> 0 | AC49: =SUM(S49:W49) -> 0 | AD49: =S49 -> 0 | AE49: -21 | AF49: =LCOE!E75+LCOE!D$40 -> 0 | AG49: =(1+AF49)^A49 -> 1 | AH49: =Z49/AG49 -> 0 | AI49: =AA49/AG49 -> 0 | AJ49: =AB49/AG49 -> 0 | AK49: =AC49/AG49 -> 0 | AL49: =AD49/AG49 -> 0
A50: -20 | B50: =LCOE!C76+IF(A50>=((LCOE!D$17*-1)+1),LCOE!D$38/LCOE!D$17,0) -> 0 | Z50: =SUM(B50:C50) -> 0 | AA50: =SUM(I50:J50) -> 0 | AB50: =L50 -> 0 | AC50: =SUM(S50:W50) -> 0 | AD50: =S50 -> 0 | AE50: -20 | AF50: =LCOE!E76+LCOE!D$40 -> 0 | AG50: =(1+AF50)^A50 -> 1 | AH50: =Z50/AG50 -> 0 | AI50: =AA50/AG50 -> 0 | AJ50: =AB50/AG50 -> 0 | AK50: =AC50/AG50 -> 0 | AL50: =AD50/AG50 -> 0
A51: -19 | B51: =LCOE!C77+IF(A51>=((LCOE!D$17*-1)+1),LCOE!D$38/LCOE!D$17,0) -> 0 | Z51: =SUM(B51:C51) -> 0 | AA51: =SUM(I51:J51) -> 0 | AB51: =L51 -> 0 | AC51: =SUM(S51:W51) -> 0 | AD51: =S51 -> 0 | AE51: -19 | AF51: =LCOE!E77+LCOE!D$40 -> 0 | AG51: =(1+AF51)^A51 -> 1 | AH51: =Z51/AG51 -> 0 | AI51: =AA51/AG51 -> 0 | AJ51: =AB51/AG51 -> 0 | AK51: =AC51/AG51 -> 0 | AL51: =AD51/AG51 -> 0
A52: -18 | B52: =LCOE!C78+IF(A52>=((LCOE!D$17*-1)+1),LCOE!D$38/LCOE!D$17,0) -> 0 | Z52: =SUM(B52:C52) -> 0 | AA52: =SUM(I52:J52) -> 0 | AB52: =L52 -> 0 | AC52: =SUM(S52:W52) -> 0 | AD52: =S52 -> 0 | AE52: -18 | AF52: =LCOE!E78+LCOE!D$40 -> 0 | AG52: =(1+AF52)^A52 -> 1 | AH52: =Z52/AG52 -> 0 | AI52: =AA52/AG52 -> 0 | AJ52: =AB52/AG52 -> 0 | AK52: =AC52/AG52 -> 0 | AL52: =AD52/AG52 -> 0
A53: -17 | B53: =LCOE!C79+IF(A53>=((LCOE!D$17*-1)+1),LCOE!D$38/LCOE!D$17,0) -> 0 | Z53: =SUM(B53:C53) -> 0 | AA53: =SUM(I53:J53) -> 0 | AB53: =L53 -> 0 | AC53: =SUM(S53:W53) -> 0 | AD53: =S53 -> 0 | AE53: -17 | AF53: =LCOE!E79+LCOE!D$40 -> 0 | AG53: =(1+AF53)^A53 -> 1 | AH53: =Z53/AG53 -> 0 | AI53: =AA53/AG53 -> 0 | AJ53: =AB53/AG53 -> 0 | AK53: =AC53/AG53 -> 0 | AL53: =AD53/AG53 -> 0
A54: -16 | B54: =LCOE!C80+IF(A54>=((LCOE!D$17*-1)+1),LCOE!D$38/LCOE!D$17,0) -> 0 | Z54: =SUM(B54:C54) -> 0 | AA54: =SUM(I54:J54) -> 0 | AB54: =L54 -> 0 | AC54: =SUM(S54:W54) -> 0 | AD54: =S54 -> 0 | AE54: -16 | AF54: =LCOE!E80+LCOE!D$40 -> 0 | AG54: =(1+AF54)^A54 -> 1 | AH54: =Z54/AG54 -> 0 | AI54: =AA54/AG54 -> 0 | AJ54: =AB54/AG54 -> 0 | AK54: =AC54/AG54 -> 0 | AL54: =AD54/AG54 -> 0
A55: -15 | B55: =LCOE!C81+IF(A55>=((LCOE!D$17*-1)+1),LCOE!D$38/LCOE!D$17,0) -> 0 | Z55: =SUM(B55:C55) -> 0 | AA55: =SUM(I55:J55) -> 0 | AB55: =L55 -> 0 | AC55: =SUM(S55:W55) -> 0 | AD55: =S55 -> 0 | AE55: -15 | AF55: =LCOE!E81+LCOE!D$40 -> 0 | AG55: =(1+AF55)^A55 -> 1 | AH55: =Z55/AG55 -> 0 | AI55: =AA55/AG55 -> 0 | AJ55: =AB55/AG55 -> 0 | AK55: =AC55/AG55 -> 0 | AL55: =AD55/AG55 -> 0
A56: -14 | B56: =LCOE!C82+IF(A56>=((LCOE!D$17*-1)+1),LCOE!D$38/LCOE!D$17,0) -> 0 | Z56: =SUM(B56:C56) -> 0 | AA56: =SUM(I56:J56) -> 0 | AB56: =L56 -> 0 | AC56: =SUM(S56:W56) -> 0 | AD56: =S56 -> 0 | AE56: -14 | AF56: =LCOE!E82+LCOE!D$40 -> 0 | AG56: =(1+AF56)^A56 -> 1 | AH56: =Z56/AG56 -> 0 | AI56: =AA56/AG56 -> 0 | AJ56: =AB56/AG56 -> 0 | AK56: =AC56/AG56 -> 0 | AL56: =AD56/AG56 -> 0
... A69: -1 | B69: =LCOE!C95+IF(A69>=((LCOE!D$17*-1)+1),LCOE!D$38/LCOE!D$17,0) -> 1.6816667e+08 | Z69: =SUM(B69:C69) -> 1.6816667e+08 | AA69: =SUM(I69:J69) -> 0 | AB69: =L69 -> 0 | AC69: =SUM(S69:W69) -> 0 | AD69: =S69 -> 0 | AE69: -1 | AF69: =LCOE!E95+LCOE!D$40 -> 0 | AG69: =(1+AF69)^A69 -> 1 | AH69: =Z69/AG69 -> 1.6816667e+08 | AI69: =AA69/AG69 -> 0 | AJ69: =AB69/AG69 -> 0 | AK69: =AC69/AG69 -> 0 | AL69: =AD69/AG69 -> 0
A70: 0 | B70: =LCOE!C96+IF(A70>=((LCOE!D$17*-1)+1),LCOE!D$38/LCOE!D$17,0) -> 1.6816667e+08 | C70: =LCOE!D96+IF(AND(LCOE!D$26>0,A70>=LCOE!D$26,A70<=(LCOE!D$26+LCOE!D$27-1)),LCOE!D$42/LCOE!D$27,0)+IF(AND(AE70>=LCOE!D$16,COUNTIF(AE45:AE70,LCOE!D$16)=LCOE!D$36+1),LCOE!D$35*LCOE!D$38,0) -> 0 | D70: =IF(AE69<LCOE!D$16,1,0) -> 1 | E70: =LCOE!G96+IF(AND(A70>=LCOE!D$26,A70<=(LCOE!D$26+LCOE!D$27-1)),0,1)*IF(A70=LCOE!D$34,0,1)*D70 -> 1 | F70: =LCOE!D$18*50%+LCOE!J96 -> 0.45 | G70: =LCOE!K96+E70*F70*N70*(LCOE!D$14+LCOE!H96)*24*365*D70 -> 1971000 | H70: =LCOE!L96+F70*(LCOE!D$15+LCOE!I96)*E70*24*365*D70*N70 -> 0 | I70: =LCOE!M96+LCOE!D$20*IF(LCOE!D$14>0,(LCOE!D$14+LCOE!H96),(LCOE!D$15+LCOE!I96))*K70*D70 -> 20000000 | J70: =LCOE!N96+LCOE!D$21*IF(LCOE!D$14>0,G70,H70)*K70*D70 -> 0 | K70: =LCOE!O96+100% -> 1 | L70: =LCOE!P96+LCOE!D$23*IF(LCOE!D$14>0,G70,H70)*M70*D70 -> 84082860 | M70: =LCOE!Q96+100% -> 1 | N70: =LCOE!R96+100% -> 1 | O70: =LCOE!S96+LCOE!D$29 -> 313.75 | P70: =LCOE!T96+IF(A70>=LCOE!D$30,100%,0%) -> 1 | Q70: =LCOE!U96+O70/1000*IF(LCOE!D$14>0,G70,H70) -> 618401.25 | R70: =LCOE!B96 -> 30 | S70: =LCOE!V96+Q70*P70*R70 -> 18552038 | T70: =LCOE!W96+LCOE!D$31 -> 0 | U70: =LCOE!X96+T70*IF(LCOE!D$14>0,G70,H70) -> 0 | V70: =LCOE!Y96+LCOE!D$32 -> 0 | W70: =LCOE!Z96+V70*IF(LCOE!D$14>0,G70,H70) -> 0 | X70: =LCOE!AA96+LCOE!D$34 -> 101 | Y70: =X70*H70 -> 0 | Z70: =SUM(B70:C70) -> 1.6816667e+08 | AA70: =SUM(I70:J70) -> 20000000 | AB70: =L70 -> 84082860 | AC70: =U70+W70 -> 0 | AD70: =S70 -> 18552038 | AE70: 0 | AF70: =LCOE!E96+LCOE!D$40 -> 0 | AG70: =(1+AF70)^A70 -> 1 | AH70: =Z70/AG70 -> 1.6816667e+08 | AI70: =AA70/AG70 -> 20000000 | AJ70: =AB70/AG70 -> 84082860 | AK70: =AC70/AG70 -> 0 | AL70: =AD70/AG70 -> 18552038 | AM70: =(-1)*Y70/AG70 -> 0 | AN70: =IF(LCOE!D$14>0,G70,H70)/AG70 -> 1971000
A71: 1 | C71: =LCOE!D97+IF(AND(LCOE!D$26>0,A71>=LCOE!D$26,A71<=(LCOE!D$26+LCOE!D$27-1)),LCOE!D$42/LCOE!D$27,0)+IF(AND(AE71>=LCOE!D$16,COUNTIF(AE46:AE71,LCOE!D$16)=LCOE!D$36+1),LCOE!D$35*LCOE!D$38,0) -> 0 | D71: =IF(AE70<LCOE!D$16,1,0) -> 1 | E71: =LCOE!G97+IF(AND(A71>=LCOE!D$26,A71<=(LCOE!D$26+LCOE!D$27-1)),0,1)*IF(A71=LCOE!D$34,0,1)*D71 -> 1 | F71: =IF(F70<LCOE!D$18,MIN(F70*(1+LCOE!D$19),LCOE!D$18),LCOE!D$18)+LCOE!J97 -> 0.72 | G71: =LCOE!K97+E71*F71*N71*(LCOE!D$14+LCOE!H97)*24*365*D71 -> 3153600 | H71: =LCOE!L97+F71*(LCOE!D$15+LCOE!I97)*E71*24*365*D71*N71 -> 0 | I71: =LCOE!M97+LCOE!D$20*IF(LCOE!D$14>0,(LCOE!D$14+LCOE!H97),(LCOE!D$15+LCOE!I97))*K71*D71 -> 20000000 | J71: =LCOE!N97+LCOE!D$21*IF(LCOE!D$14>0,G71,H71)*K71*D71 -> 0 | K71: =LCOE!O97+K70+K70*LCOE!D$22 -> 1 | L71: =LCOE!P97+LCOE!D$23*IF(LCOE!D$14>0,G71,H71)*M71*D71 -> 134532576 | M71: =LCOE!Q97+M70+M70*LCOE!D$24 -> 1 | N71: =LCOE!R97+N70-N70*LCOE!D$25 -> 1 | O71: =LCOE!S97+LCOE!D$29 -> 313.75 | P71: =LCOE!T97+IF(A71>=LCOE!D$30,100%,0%) -> 1 | Q71: =LCOE!U97+O71/1000*IF(LCOE!D$14>0,G71,H71) -> 989442 | R71: =LCOE!B97 -> 30 | S71: =LCOE!V97+Q71*P71*R71 -> 29683260 | T71: =LCOE!W97+LCOE!D$31 -> 0 | U71: =LCOE!X97+T71*IF(LCOE!D$14>0,G71,H71) -> 0 | V71: =LCOE!Y97+LCOE!D$32 -> 0 | W71: =LCOE!Z97+V71*IF(LCOE!D$14>0,G71,H71) -> 0 | X71: =LCOE!AA97+LCOE!D$34 -> 101 | Y71: =X71*H71 -> 0 | Z71: =SUM(B71:C71) -> 0 | AA71: =SUM(I71:J71) -> 20000000 | AB71: =L71 -> 134532576 | AC71: =U71+W71 -> 0 | AD71: =S71 -> 29683260 | AE71: =AE70+1*E71 -> 1 | AF71: =LCOE!E97+LCOE!D$40 -> 0 | AG71: =(1+AF71)^A71 -> 1 | AH71: =Z71/AG71 -> 0 | AI71: =AA71/AG71 -> 20000000 | AJ71: =AB71/AG71 -> 134532576 | AK71: =AC71/AG71 -> 0 | AL71: =AD71/AG71 -> 29683260 | AM71: =(-1)*Y71/AG71 -> 0 | AN71: =IF(LCOE!D$14>0,G71,H71)/AG71 -> 3153600
...

Sheet LCOE 2
B2: Parameter recap (not used in calcs) | C2: =LCOE!E3 -> LCOE 2 | F2: RESULTS | G2: =C4 -> USD | I2: =C6 -> USD
B3: =LCOE!C5 -> Name | C3: =LCOE!E5 -> CCGT in Belgium (2020) | F3: =LCOE!C46 -> LCOE (LCOHeat for pure heat plants) | G3: =SUM(AH45:AM170)/SUM(AN45:AN170) -> 64.075543 | H3: =_xlfn.CONCAT(C$4,"/MWh") -> USD/MWh | I3: =G3*C$7 -> 64.075543 | J3: =_xlfn.CONCAT(C$6,"/MWh") -> USD/MWh
B4: =LCOE!C6 -> Currency used for LCOE calculations | C4: =LCOE!E6 -> USD | F4: =LCOE!C47 -> Of which: Capital costs | G4: =SUM(AH45:AH170)/SUM(AN45:AN170) -> 6.7525504 | H4: =_xlfn.CONCAT(C$4,"/MWh") -> USD/MWh | I4: =G4*C$7 -> 6.7525504 | J4: =_xlfn.CONCAT(C$6,"/MWh") -> USD/MWh
B5: =LCOE!C7 -> Price reference year | C5: =LCOE!E7 -> 0 | F5: =LCOE!C48 -> O&M | G5: =SUM(AI45:AI170)/SUM(AN45:AN170) -> 5.250493 | H5: =_xlfn.CONCAT(C$4,"/MWh") -> USD/MWh | I5: =G5*C$7 -> 5.250493 | J5: =_xlfn.CONCAT(C$6,"/MWh") -> USD/MWh
B6: =LCOE!C8 -> Currency used | C6: =LCOE!E8 -> USD | F6: =LCOE!C49 -> Fuel | G6: =SUM(AJ45:AJ170)/SUM(AN45:AN170) -> 42.66 | H6: =_xlfn.CONCAT(C$4,"/MWh") -> USD/MWh | I6: =G6*C$7 -> 42.66 | J6: =_xlfn.CONCAT(C$6,"/MWh") -> USD/MWh
B7: =LCOE!C9 -> Conversion rate at reference year | C7: =LCOE!E9 -> 1 | F7: =LCOE!C50 -> Taxes and fees | G7: =SUM(AK45:AK170)/SUM(AN45:AN170) -> 0 | H7: =_xlfn.CONCAT(C$4,"/MWh") -> USD/MWh | I7: =G7*C$7 -> 0 | J7: =_xlfn.CONCAT(C$6,"/MWh") -> USD/MWh
B8: =LCOE!C10 -> Debt % | C8: =LCOE!E10 -> 0.9 | F8: =LCOE!C51 -> Emission costs | G8: =SUM(AL45:AL170)/SUM(AN45:AN170) -> 9.4125 | H8: =_xlfn.CONCAT(C$4,"/MWh") -> USD/MWh | I8: =G8*C$7 -> 9.4125 | J8: =_xlfn.CONCAT(C$6,"/MWh") -> USD/MWh
B9: =LCOE!C11 -> Cost of debt (private discount rate) | C9: =LCOE!E11 -> 0.03 | F9: =LCOE!C52 -> Heat credit (for CHP plants) | G9: =IF(C15>0,SUM(AM45:AM170)/SUM(AN45:AN170),0) -> 0 | H9: =_xlfn.CONCAT(C$4,"/MWh") -> USD/MWh | I9: =G9*C$7 -> 0 | J9: =_xlfn.CONCAT(C$6,"/MWh") -> USD/MWh
B10: =LCOE!C12 -> Cost of equity (discount rate) | C10: =LCOE!E12 -> 0.03 | F10: =LCOE!C53 -> WACC average over lifetime | G10: =AVERAGE(AF70:AF170) -> 0.03 | I10: =G10 -> 0.03
B11: =LCOE!C13 -> Construction cost per kW | C11: =LCOE!E13 -> 1009 | F11: =LCOE!C54 -> Plant type | G11: =IF(AND(LCOE!E$14>0,LCOE!E$15=0),"Electric only",IF(AND(LCOE!E$14>0,LCOE!E$15>0),"CHP",IF(AND(LCOE!E$14=0,LCOE!E$15>0),"Heat only","Error: no generation"))) -> Electric only | I11: =G11 -> Electric only
B12: =LCOE!C14 -> Maximum electric power, in MW_e | C12: =LCOE!E14 -> 500
B13: =LCOE!C15 -> Maximum heat power, in MW_h | C13: =LCOE!E15 -> 0
B14: =LCOE!C16 -> Plant lifetime | C14: =LCOE!E16 -> 30
B15: =LCOE!C17 -> Construction period, years | C15: =LCOE!E17 -> 3
B16: =LCOE!C18 -> Capacity factor (settled down) | C16: =LCOE!E18 -> 0.9
B17: =LCOE!C19 -> Capacity factor ramp-up on startup, per year | C17: =LCOE!E19 -> 0.6
B18: =LCOE!C20 -> Fixed OPEX/MW capacity at project start | C18: =LCOE!E20 -> 40000
B19: =LCOE!C21 -> Variable OPEX/MWh produced at project start | C19: =LCOE!E21 -> 0
B20: =LCOE!C22 -> OPEX escalator | C20: =LCOE!E22 -> 0
B21: =LCOE!C23 -> FUELEX/MWh produced at project start | C21: =LCOE!E23 -> 42.66
B22: =LCOE!C24 -> FUELEX escalator | C22: =LCOE!E24 -> 0
B23: =LCOE!C25 -> Efficiency loss/year | C23: =LCOE!E25 -> 0
... B41: =LCOE!C43 -> Overrides | C41: =LCOE!E43 -> 0
Z43: SUMMARY OF COSTS
A44: Year (t) | B44: CAPEXconstr | C44: CAPEXrefurb/decom | D44: Lifetime left? | E44: Operational% | F44: Capacity factor | G44: Electricity produced (MWh_e) | H44: Heat produced (MWh_h) | I44: Fixed OPEX | J44: Variable OPEX | K44: OPEX relative to startup | L44: FUELEX | M44: FUELEX relative to startup | N44: Efficiency relative to startup | O44: Total emission factor, gCO2/kWh | P44: % of emissions taxed | Q44: Total emissions, tCO2e | R44: Cost of tCO2e | S44: Cost of emissions levied, E | T44: Tax per MWh produced | U44: Taxes levied | V44: Waste fee per MWh produced | W44: Waste fee levied | X44: Heat credit per MWh_h | Y44: Heat credit total | Z44: Total capital expenditure, I | AA44: Total operation and maintenance expenditure, M | AB44: Total fuel expenditure, F | AC44: Total taxes, T | AD44: Total emission fees, E | AE44: Lifetime expended at start of year | AF44: Discount rate r (IDC when t<0) | AG44: Discount factor (1+r)^t | AH44: I discounted | AI44: M discounted | AJ44: F discounted | AK44: T discounted | AL44: E discounted | AM44: Heat credit, discounted | AN44: Production (MWh), discounted
A45: -25 | B45: =LCOE!C71+IF(A45>=((LCOE!E$17*-1)+1),LCOE!E$38/LCOE!E$17,0) -> 0 | Z45: =SUM(B45:C45) -> 0 | AA45: =SUM(I45:J45) -> 0 | AB45: =L45 -> 0 | AC45: =SUM(S45:W45) -> 0 | AD45: =S45 -> 0 | AE45: -25 | AF45: =LCOE!E71+LCOE!E$40 -> 0.03 | AG45: =(1+AF45)^A45 -> 0.47760557 | AH45: =Z45/AG45 -> 0 | AI45: =AA45/AG45 -> 0 | AJ45: =AB45/AG45 -> 0 | AK45: =AC45/AG45 -> 0 | AL45: =AD45/AG45 -> 0
A46: -24 | B46: =LCOE!C72+IF(A46>=((LCOE!E$17*-1)+1),LCOE!E$38/LCOE!E$17,0) -> 0 | Z46: =SUM(B46:C46) -> 0 | AA46: =SUM(I46:J46) -> 0 | AB46: =L46 -> 0 | AC46: =SUM(S46:W46) -> 0 | AD46: =S46 -> 0 | AE46: -24 | AF46: =LCOE!E72+LCOE!E$40 -> 0.03 | AG46: =(1+AF46)^A46 -> 0.49193374 | AH46: =Z46/AG46 -> 0 | AI46: =AA46/AG46 -> 0 | AJ46: =AB46/AG46 -> 0 | AK46: =AC46/AG46 -> 0 | AL46: =AD46/AG46 -> 0
A47: -23 | B47: =LCOE!C73+IF(A47>=((LCOE!E$17*-1)+1),LCOE!E$38/LCOE!E$17,0) -> 0 | Z47: =SUM(B47:C47) -> 0 | AA47: =SUM(I47:J47) -> 0 | AB47: =L47 -> 0 | AC47: =SUM(S47:W47) -> 0 | AD47: =S47 -> 0 | AE47: -23 | AF47: =LCOE!E73+LCOE!E$40 -> 0.03 | AG47: =(1+AF47)^A47 -> 0.50669175 | AH47: =Z47/AG47 -> 0 | AI47: =AA47/AG47 -> 0 | AJ47: =AB47/AG47 -> 0 | AK47: =AC47/AG47 -> 0 | AL47: =AD47/AG47 -> 0
A48: -22 | B48: =LCOE!C74+IF(A48>=((LCOE!E$17*-1)+1),LCOE!E$38/LCOE!E$17,0) -> 0 | Z48: =SUM(B48:C48) -> 0 | AA48: =SUM(I48:J48) -> 0 | AB48: =L48 -> 0 | AC48: =SUM(S48:W48) -> 0 | AD48: =S48 -> 0 | AE48: -22 | AF48: =LCOE!E74+LCOE!E$40 -> 0.03 | AG48: =(1+AF48)^A48 -> 0.5218925 | AH48: =Z48/AG48 -> 0 | AI48: =AA48/AG48 -> 0 | AJ48: =AB48/AG48 -> 0 | AK48: =AC48/AG48 -> 0 | AL48: =AD48/AG48 -> 0
A49: -21 | B49: =LCOE!C75+IF(A49>=((LCOE!E$17*-1)+1),LCOE!E$38/LCOE!E$17,0) -> 0 | Z49: =SUM(B49:C49) -> 0 | AA49: =SUM(I49:J49) -> 0 | AB49: =L49 -> 0 | AC49: =SUM(S49:W49) -> 0 | AD49: =S49 -> 0 | AE49: -21 | AF49: =LCOE!E75+LCOE!E$40 -> 0.03 | AG49: =(1+AF49)^A49 -> 0.53754928 | AH49: =Z49/AG49 -> 0 | AI49: =AA49/AG49 -> 0 | AJ49: =AB49/AG49 -> 0 | AK49: =AC49/AG49 -> 0 | AL49: =AD49/AG49 -> 0
A50: -20 | B50: =LCOE!C76+IF(A50>=((LCOE!E$17*-1)+1),LCOE!E$38/LCOE!E$17,0) -> 0 | Z50: =SUM(B50:C50) -> 0 | AA50: =SUM(I50:J50) -> 0 | AB50: =L50 -> 0 | AC50: =SUM(S50:W50) -> 0 | AD50: =S50 -> 0 | AE50: -20 | AF50: =LCOE!E76+LCOE!E$40 -> 0.03 | AG50: =(1+AF50)^A50 -> 0.55367575 | AH50: =Z50/AG50 -> 0 | AI50: =AA50/AG50 -> 0 | AJ50: =AB50/AG50 -> 0 | AK50: =AC50/AG50 -> 0 | AL50: =AD50/AG50 -> 0
A51: -19 | B51: =LCOE!C77+IF(A51>=((LCOE!E$17*-1)+1),LCOE!E$38/LCOE!E$17,0) -> 0 | Z51: =SUM(B51:C51) -> 0 | AA51: =SUM(I51:J51) -> 0 | AB51: =L51 -> 0 | AC51: =SUM(S51:W51) -> 0 | AD51: =S51 -> 0 | AE51: -19 | AF51: =LCOE!E77+LCOE!E$40 -> 0.03 | AG51: =(1+AF51)^A51 -> 0.57028603 | AH51: =Z51/AG51 -> 0 | AI51: =AA51/AG51 -> 0 | AJ51: =AB51/AG51 -> 0 | AK51: =AC51/AG51 -> 0 | AL51: =AD51/AG51 -> 0
A52: -18 | B52: =LCOE!C78+IF(A52>=((LCOE!E$17*-1)+1),LCOE!E$38/LCOE!E$17,0) -> 0 | Z52: =SUM(B52:C52) -> 0 | AA52: =SUM(I52:J52) -> 0 | AB52: =L52 -> 0 | AC52: =SUM(S52:W52) -> 0 | AD52: =S52 -> 0 | AE52: -18 | AF52: =LCOE!E78+LCOE!E$40 -> 0.03 | AG52: =(1+AF52)^A52 -> 0.58739461 | AH52: =Z52/AG52 -> 0 | AI52: =AA52/AG52 -> 0 | AJ52: =AB52/AG52 -> 0 | AK52: =AC52/AG52 -> 0 | AL52: =AD52/AG52 -> 0
A53: -17 | B53: =LCOE!C79+IF(A53>=((LCOE!E$17*-1)+1),LCOE!E$38/LCOE!E$17,0) -> 0 | Z53: =SUM(B53:C53) -> 0 | AA53: =SUM(I53:J53) -> 0 | AB53: =L53 -> 0 | AC53: =SUM(S53:W53) -> 0 | AD53: =S53 -> 0 | AE53: -17 | AF53: =LCOE!E79+LCOE!E$40 -> 0.03 | AG53: =(1+AF53)^A53 -> 0.60501645 | AH53: =Z53/AG53 -> 0 | AI53: =AA53/AG53 -> 0 | AJ53: =AB53/AG53 -> 0 | AK53: =AC53/AG53 -> 0 | AL53: =AD53/AG53 -> 0
A54: -16 | B54: =LCOE!C80+IF(A54>=((LCOE!E$17*-1)+1),LCOE!E$38/LCOE!E$17,0) -> 0 | Z54: =SUM(B54:C54) -> 0 | AA54: =SUM(I54:J54) -> 0 | AB54: =L54 -> 0 | AC54: =SUM(S54:W54) -> 0 | AD54: =S54 -> 0 | AE54: -16 | AF54: =LCOE!E80+LCOE!E$40 -> 0.03 | AG54: =(1+AF54)^A54 -> 0.62316694 | AH54: =Z54/AG54 -> 0 | AI54: =AA54/AG54 -> 0 | AJ54: =AB54/AG54 -> 0 | AK54: =AC54/AG54 -> 0 | AL54: =AD54/AG54 -> 0
A55: -15 | B55: =LCOE!C81+IF(A55>=((LCOE!E$17*-1)+1),LCOE!E$38/LCOE!E$17,0) -> 0 | Z55: =SUM(B55:C55) -> 0 | AA55: =SUM(I55:J55) -> 0 | AB55: =L55 -> 0 | AC55: =SUM(S55:W55) -> 0 | AD55: =S55 -> 0 | AE55: -15 | AF55: =LCOE!E81+LCOE!E$40 -> 0.03 | AG55: =(1+AF55)^A55 -> 0.64186195 | AH55: =Z55/AG55 -> 0 | AI55: =AA55/AG55 -> 0 | AJ55: =AB55/AG55 -> 0 | AK55: =AC55/AG55 -> 0 | AL55: =AD55/AG55 -> 0
A56: -14 | B56: =LCOE!C82+IF(A56>=((LCOE!E$17*-1)+1),LCOE!E$38/LCOE!E$17,0) -> 0 | Z56: =SUM(B56:C56) -> 0 | AA56: =SUM(I56:J56) -> 0 | AB56: =L56 -> 0 | AC56: =SUM(S56:W56) -> 0 | AD56: =S56 -> 0 | AE56: -14 | AF56: =LCOE!E82+LCOE!E$40 -> 0.03 | AG56: =(1+AF56)^A56 -> 0.66111781 | AH56: =Z56/AG56 -> 0 | AI56: =AA56/AG56 -> 0 | AJ56: =AB56/AG56 -> 0 | AK56: =AC56/AG56 -> 0 | AL56: =AD56/AG56 -> 0
... A69: -1 | B69: =LCOE!C95+IF(A69>=((LCOE!E$17*-1)+1),LCOE!E$38/LCOE!E$17,0) -> 1.6816667e+08 | Z69: =SUM(B69:C69) -> 1.6816667e+08 | AA69: =SUM(I69:J69) -> 0 | AB69: =L69 -> 0 | AC69: =SUM(S69:W69) -> 0 | AD69: =S69 -> 0 | AE69: -1 | AF69: =LCOE!E95+LCOE!E$40 -> 0.03 | AG69: =(1+AF69)^A69 -> 0.97087379 | AH69: =Z69/AG69 -> 1.7321167e+08 | AI69: =AA69/AG69 -> 0 | AJ69: =AB69/AG69 -> 0 | AK69: =AC69/AG69 -> 0 | AL69: =AD69/AG69 -> 0
A70: 0 | B70: =LCOE!C96+IF(A70>=((LCOE!E$17*-1)+1),LCOE!E$38/LCOE!E$17,0) -> 1.6816667e+08 | C70: =LCOE!E96+IF(AND(LCOE!E$26>0,A70>=LCOE!E$26,A70<=(LCOE!E$26+LCOE!E$27-1)),LCOE!E$42/LCOE!E$27,0)+IF(AND(D70=0,AE70>=LCOE!E$16,COUNTIF(D45:D70,0)=LCOE!E$36),LCOE!E$35*LCOE!E$38,0) -> 0 | D70: =IF(AE69<LCOE!E$16,1,0) -> 1 | E70: =LCOE!G96+IF(AND(A70>=LCOE!E$26,A70<=(LCOE!E$26+LCOE!E$27-1)),0,1)*IF(A70=LCOE!E$34,0,1)*D70 -> 1 | F70: =LCOE!E$18*50%+LCOE!J96 -> 0.45 | G70: =LCOE!K96+E70*F70*N70*(LCOE!E$14+LCOE!H96)*24*365*D70 -> 1971000 | H70: =LCOE!L96+F70*(LCOE!E$15+LCOE!I96)*E70*24*365*D70*N70 -> 0 | I70: =LCOE!M96+LCOE!E$20*IF(LCOE!E$14>0,(LCOE!E$14+LCOE!H96),(LCOE!E$15+LCOE!I96))*K70*D70 -> 20000000 | J70: =LCOE!N96+LCOE!E$21*IF(LCOE!E$14>0,G70,H70)*K70*D70 -> 0 | K70: =LCOE!O96+100% -> 1 | L70: =LCOE!P96+LCOE!E$23*IF(LCOE!E$14>0,G70,H70)*M70*D70 -> 84082860 | M70: =LCOE!Q96+100% -> 1 | N70: =LCOE!R96+100% -> 1 | O70: =LCOE!S96+LCOE!E$29 -> 313.75 | P70: =LCOE!T96+IF(A70>=LCOE!E$30,100%,0%) -> 1 | Q70: =LCOE!U96+O70/1000*IF(LCOE!E$14>0,G70,H70) -> 618401.25 | R70: =LCOE!B96 -> 30 | S70: =LCOE!V96+Q70*P70*R70 -> 18552038 | T70: =LCOE!W96+LCOE!E$31 -> 0 | U70: =LCOE!X96+T70*IF(LCOE!E$14>0,G70,H70) -> 0 | V70: =LCOE!Y96+LCOE!E$32 -> 0 | W70: =LCOE!Z96+V70*IF(LCOE!E$14>0,G70,H70) -> 0 | X70: =LCOE!AA96+LCOE!E$34 -> 101 | Y70: =X70*H70 -> 0 | Z70: =SUM(B70:C70) -> 1.6816667e+08 | AA70: =SUM(I70:J70) -> 20000000 | AB70: =L70 -> 84082860 | AC70: =U70+W70 -> 0 | AD70: =S70 -> 18552038 | AE70: 0 | AF70: =LCOE!E96+LCOE!E$40 -> 0.03 | AG70: =(1+AF70)^A70 -> 1 | AH70: =Z70/AG70 -> 1.6816667e+08 | AI70: =AA70/AG70 -> 20000000 | AJ70: =AB70/AG70 -> 84082860 | AK70: =AC70/AG70 -> 0 | AL70: =AD70/AG70 -> 18552038 | AM70: =(-1)*Y70/AG70 -> 0 | AN70: =IF(LCOE!E$14>0,G70,H70)/AG70 -> 1971000
A71: 1 | C71: =LCOE!E97+IF(AND(LCOE!E$26>0,A71>=LCOE!E$26,A71<=(LCOE!E$26+LCOE!E$27-1)),LCOE!E$42/LCOE!E$27,0)+IF(AND(D71=0,AE71>=LCOE!E$16,COUNTIF(D46:D71,0)=LCOE!E$36),LCOE!E$35*LCOE!E$38,0) -> 0 | D71: =IF(AE70<LCOE!E$16,1,0) -> 1 | E71: =LCOE!G97+IF(AND(A71>=LCOE!E$26,A71<=(LCOE!E$26+LCOE!E$27-1)),0,1)*IF(A71=LCOE!E$34,0,1)*D71 -> 1 | F71: =IF(F70<LCOE!E$18,MIN(F70*(1+LCOE!E$19),LCOE!E$18),LCOE!E$18)+LCOE!J97 -> 0.72 | G71: =LCOE!K97+E71*F71*N71*(LCOE!E$14+LCOE!H97)*24*365*D71 -> 3153600 | H71: =LCOE!L97+F71*(LCOE!E$15+LCOE!I97)*E71*24*365*D71*N71 -> 0 | I71: =LCOE!M97+LCOE!E$20*IF(LCOE!E$14>0,(LCOE!E$14+LCOE!H97),(LCOE!E$15+LCOE!I97))*K71*D71 -> 20000000 | J71: =LCOE!N97+LCOE!E$21*IF(LCOE!E$14>0,G71,H71)*K71*D71 -> 0 | K71: =LCOE!O97+K70+K70*LCOE!E$22 -> 1 | L71: =LCOE!P97+LCOE!E$23*IF(LCOE!E$14>0,G71,H71)*M71*D71 -> 134532576 | M71: =LCOE!Q97+M70+M70*LCOE!E$24 -> 1 | N71: =LCOE!R97+N70-N70*LCOE!E$25 -> 1 | O71: =LCOE!S97+LCOE!E$29 -> 313.75 | P71: =LCOE!T97+IF(A71>=LCOE!E$30,100%,0%) -> 1 | Q71: =LCOE!U97+O71/1000*IF(LCOE!E$14>0,G71,H71) -> 989442 | R71: =LCOE!B97 -> 30 | S71: =LCOE!V97+Q71*P71*R71 -> 29683260 | T71: =LCOE!W97+LCOE!E$31 -> 0 | U71: =LCOE!X97+T71*IF(LCOE!E$14>0,G71,H71) -> 0 | V71: =LCOE!Y97+LCOE!E$32 -> 0 | W71: =LCOE!Z97+V71*IF(LCOE!E$14>0,G71,H71) -> 0 | X71: =LCOE!AA97+LCOE!E$34 -> 101 | Y71: =X71*H71 -> 0 | Z71: =SUM(B71:C71) -> 0 | AA71: =SUM(I71:J71) -> 20000000 | AB71: =L71 -> 134532576 | AC71: =U71+W71 -> 0 | AD71: =S71 -> 29683260 | AE71: =AE70+1*E71 -> 1 | AF71: =LCOE!E97+LCOE!E$40 -> 0.03 | AG71: =(1+AF71)^A71 -> 1.03 | AH71: =Z71/AG71 -> 0 | AI71: =AA71/AG71 -> 19417476 | AJ71: =AB71/AG71 -> 1.3061415e+08 | AK71: =AC71/AG71 -> 0 | AL71: =AD71/AG71 -> 28818699 | AM71: =(-1)*Y71/AG71 -> 0 | AN71: =IF(LCOE!E$14>0,G71,H71)/AG71 -> 3061747.6
...

Sheet LCOE 3
B2: Parameter recap (not used in calcs) | C2: =LCOE!F3 -> LCOE 3 | F2: RESULTS | G2: =C4 -> USD | I2: =C6 -> USD
B3: =LCOE!C5 -> Name | C3: =LCOE!F5 -> CCGT in Belgium (2020) | F3: =LCOE!C46 -> LCOE (LCOHeat for pure heat plants) | G3: =SUM(AH45:AM170)/SUM(AN45:AN170) -> 66.035232 | H3: =_xlfn.CONCAT(C$4,"/MWh") -> USD/MWh | I3: =G3*C$7 -> 66.035232 | J3: =_xlfn.CONCAT(C$6,"/MWh") -> USD/MWh
B4: =LCOE!C6 -> Currency used for LCOE calculations | C4: =LCOE!F6 -> USD | F4: =LCOE!C47 -> Of which: Capital costs | G4: =SUM(AH45:AH170)/SUM(AN45:AN170) -> 8.6657769 | H4: =_xlfn.CONCAT(C$4,"/MWh") -> USD/MWh | I4: =G4*C$7 -> 8.6657769 | J4: =_xlfn.CONCAT(C$6,"/MWh") -> USD/MWh
B5: =LCOE!C7 -> Price reference year | C5: =LCOE!F7 -> 0 | F5: =LCOE!C48 -> O&M | G5: =SUM(AI45:AI170)/SUM(AN45:AN170) -> 5.2969555 | H5: =_xlfn.CONCAT(C$4,"/MWh") -> USD/MWh | I5: =G5*C$7 -> 5.2969555 | J5: =_xlfn.CONCAT(C$6,"/MWh") -> USD/MWh
B6: =LCOE!C8 -> Currency used | C6: =LCOE!F8 -> USD | F6: =LCOE!C49 -> Fuel | G6: =SUM(AJ45:AJ170)/SUM(AN45:AN170) -> 42.66 | H6: =_xlfn.CONCAT(C$4,"/MWh") -> USD/MWh | I6: =G6*C$7 -> 42.66 | J6: =_xlfn.CONCAT(C$6,"/MWh") -> USD/MWh
B7: =LCOE!C9 -> Conversion rate at reference year | C7: =LCOE!F9 -> 1 | F7: =LCOE!C50 -> Taxes and fees | G7: =SUM(AK45:AK170)/SUM(AN45:AN170) -> 0 | H7: =_xlfn.CONCAT(C$4,"/MWh") -> USD/MWh | I7: =G7*C$7 -> 0 | J7: =_xlfn.CONCAT(C$6,"/MWh") -> USD/MWh
B8: =LCOE!C10 -> Debt % | C8: =LCOE!F10 -> 0.9 | F8: =LCOE!C51 -> Emission costs | G8: =SUM(AL45:AL170)/SUM(AN45:AN170) -> 9.4125 | H8: =_xlfn.CONCAT(C$4,"/MWh") -> USD/MWh | I8: =G8*C$7 -> 9.4125 | J8: =_xlfn.CONCAT(C$6,"/MWh") -> USD/MWh
B9: =LCOE!C11 -> Cost of debt (private discount rate) | C9: =LCOE!F11 -> 0.05 | F9: =LCOE!C52 -> Heat credit (for CHP plants) | G9: =IF(C15>0,SUM(AM45:AM170)/SUM(AN45:AN170),0) -> 0 | H9: =_xlfn.CONCAT(C$4,"/MWh") -> USD/MWh | I9: =G9*C$7 -> 0 | J9: =_xlfn.CONCAT(C$6,"/MWh") -> USD/MWh
B10: =LCOE!C12 -> Cost of equity (discount rate) | C10: =LCOE!F12 -> 0.05 | F10: =LCOE!C53 -> WACC average over lifetime | G10: =AVERAGE(AF70:AF170) -> 0.05 | I10: =G10 -> 0.05
B11: =LCOE!C13 -> Construction cost per kW | C11: =LCOE!F13 -> 1009 | F11: =LCOE!C54 -> Plant type | G11: =IF(AND(LCOE!F$14>0,LCOE!F$15=0),"Electric only",IF(AND(LCOE!F$14>0,LCOE!F$15>0),"CHP",IF(AND(LCOE!F$14=0,LCOE!F$15>0),"Heat only","Error: no generation"))) -> Electric only | I11: =G11 -> Electric only
B12: =LCOE!C14 -> Maximum electric power, in MW_e | C12: =LCOE!F14 -> 500
B13: =LCOE!C15 -> Maximum heat power, in MW_h | C13: =LCOE!F15 -> 0
B14: =LCOE!C16 -> Plant lifetime | C14: =LCOE!F16 -> 30
B15: =LCOE!C17 -> Construction period, years | C15: =LCOE!F17 -> 3
B16: =LCOE!C18 -> Capacity factor (settled down) | C16: =LCOE!F18 -> 0.9
B17: =LCOE!C19 -> Capacity factor ramp-up on startup, per year | C17: =LCOE!F19 -> 0.6
B18: =LCOE!C20 -> Fixed OPEX/MW capacity at project start | C18: =LCOE!F20 -> 40000
B19: =LCOE!C21 -> Variable OPEX/MWh produced at project start | C19: =LCOE!F21 -> 0
B20: =LCOE!C22 -> OPEX escalator | C20: =LCOE!F22 -> 0
B21: =LCOE!C23 -> FUELEX/MWh produced at project start | C21: =LCOE!F23 -> 42.66
B22: =LCOE!C24 -> FUELEX escalator | C22: =LCOE!F24 -> 0
B23: =LCOE!C25 -> Efficiency loss/year | C23: =LCOE!F25 -> 0
... B41: =LCOE!C43 -> Overrides | C41: =LCOE!F43 -> 0
Z43: SUMMARY OF COSTS
