Workbook
Name Deflator_2010: #REF!
Name Deflator_2011: #REF!
Name Deflator_2012: #REF!
Name Deflator_2013: #REF!
Name Deflator_2014: #REF!
Name Deflator_2015: #REF!
Name Deflator_2016: #REF!
Name Deflator_2017: #REF!
Name Deflator_2018: #REF!

Sheet Kuvaus ja ohje
A1: Kuvaus ja ohje: LCOE-laskin, päivitetty 26.9.2023
B3: Tällä laskurilla voidaan laskea erilaisten sähköä ja lämpöä tuottavien voimaloiden niin sanottu tasoitettu tuotantokustannus LCOE (Levelized Cost Of Electricity).
B4: LCOE tarkoittaa hintaa, jonka laitoksen on keskimäärin saatava myymästään sähköstä, jotta se olisi kannattava, kun kaikki kustannukset huomioidaan.
B5: Laskuri huomioi rakentamis- ja käyttökustannusten lisäksi myös päästömaksut ja mahdolliset erityisesti laitokseen kohdistuvat verot ja maksut.
B7: Laskuri perustuu Ison-Britannian energiaministeriön (Department of Energy Security and Net Zero) 2023 julkaisemaan LCOE-laskuriin (https://www.gov.uk/government/publications/electricity-generation-costs-2023).
B8: Alkuperäinen laskuri on julkaistu Open Government v3.0-lisenssillä (http://nationalarchives.gov.uk/doc/open-government-licence/version/3/).
B9: Laskuri on lokalisoitu Suomeen muuttamalla rahayksiköt vuosien 2022 tai 2023 euroiksi (riippuen datan saatavuudesta). Siihen on myös lisätty uusia laitoksia ja toiminnallisuuksia.
B10: Lokalisoinnin ja lisäykset on toteuttanut Janne M. Korhonen, Kalevi Sorsa-säätiö (janne.korhonen@sorsafoundation.fi).
B11: Huomaa, että laskuri on vielä osin kesken, ja esimerkiksi kaikkia polttoaine- tai päästöskenaarioita ei ole vielä sisällytetty.
B12: Laskurilla voi kuitenkin laskea Sorsa-säätiön raportissa Muuttuva energiapalapeli: onko edessä vihreä humahdus?-käsiteltyjen voimaloiden LCOE:n.
B14: Miten laskuri toimii?
B15: Varsinainen laskuri löytyy välilehdeltä "LCOE EUR". Välilehdellä "Muuttujien kuvaus" on tarkempaa tietoa muuttujista.
A16: . | B16: Vaaleanpunainen väri kertoo käyttäjältä vaaditusta syötteestä:
B18: Muuttele näitä soluja!
B20: Useimmissa muutettavissa soluissa on alasvetovalikko, josta voi valita esimerkiksi eri laitoksen tai skenaariovaihtoehdon. Sen saa esiin klikkaamalla ensin solua, ja sitten alaspäin osoittavaa kolmiota.
B21: (Muutos ei välttämättä päivity automaattisesti; päivitä taulukko käsin tai tallenna se, jolloin se päivittyy.)
B23: Kohdassa "Muutokset" oleviin soluihin voi kokeilla skenaarioiden variaatioita. Kyseisiin soluihin syötetyt luvut lisätään (tai negatiivisten lukujen tapauksessa vähennetään) vastaavasta muuttujasta.
B25: Laskurin käyttämä data haetaan välilehdiltä "Laitokset," "Polttoainekustannukset," "Päästötase" ja "Päästömaksut."

Sheet Muuttujien kuvaus
A1: Muuttujien kuvaus
B3: Muuttuja | C3: Kuvaus
B4: Suunnittelukustannukset | C4: Suunnittelun, luvituksen ynnä muut kulut, jotka aiheutuvat ennen kuin laitosta ryhdytään rakentamaan. Ilmoitettu euroina nimellistehon kilowattia kohden. Kolme skenaariota: matala, keski, korkea.
B5: Suunnittelun kesto | C5: Suunnitteluvaiheen kesto vuosina. Kolme skenaariota: matala, keski, korkea.
B6: Rakentamiskustannukset | C6: Laitoksen rakentamiskustannukset. Ilmoitettu euroina nimellistehon kilowattia kohden. Kolme skenaariota: matala, keski, korkea.
B7: Rakentamisaikataulu | C7: Rakennusvaiheen kesto vuosina. Kolme skenaariota: matala, keski, korkea.
B8: Polttoaineen hintaskenaario | C8: Laskelmassa käytettävä polttoaineen hintaskenaario (välilehti Polttoainekustannukset). Useita skenaarioita.
B9: Polttoaineen päästötase | C9: Laskelmassa käytettävä arvio laitoksen käytön päästötaseesta (välilehti Päästötase). Useita skenaarioita.
B10: Päästöoikeuden hintaskenaario | C10: Laskelmassa käytettävä skenaario päästöoikeuden hinnan kehittymisestä (välilehti Päästömaksut). Useita skenaarioita.
B11: Projektin aloitusvuosi | C11: Vuosi, jolloin projektin suunnittelu aloitetaan; minimi 2020. Vaikuttaa polttoaineen ja päästöoikeuden hintaan valitun skenaarion mukaisesti.
B12: Tekniikka vuodelta | C12: Vuosi, jolloin laitoksen tekniikan uskotaan olevan valmiina kaupalliseen käyttöön, tai vuosi, jolta tiedot ovat peräisin.
B13: Rakentamisen aloitusvuosi | C13: Vuosi, jolloin laitoksen rakentaminen päästään aloittamaan. Määräytyy projektin aloitusvuoden ja suunnittelun keston perusteella.
B14: Käyttöönottovuosi | C14: Vuosi, jolloin laitos otetaan käyttöön. Määräytyy rakentamisen aloitusvuoden ja rakentamisaikataulun perusteella.
... B25: Sähkön tasoitettu tuotantokustannus (LCOE) | C25: Hinta, jonka laitoksen on saatava keskimäärin myymästään sähköstä, jotta se olisi kannattava sijoitus, kun kaikki kulut ja pääoman kustannus huomioidaan.

Sheet LCOE EUR
B1: LCOE-laskin, päivitetty 19.8.2024
B2: Pohjautuu Annex B LCOE-laskuriin | C2: Muutokset: Janne M. Korhonen, Kalevi Sorsa-säätiö
B3: (Energiaministeriö, Iso-Britannia, 2023)
B4: Jaettu Open Government v3.0-lisenssillä | D4: <- Syötteet
B6: Skenaario | E6: Huom: | H6: Skenaarion tiedot (haettu välilehdeltä Laitokset)
B7: Laitos | C7: Ydinreaktori, 1 250 MW, Ruotsi 2024 referenssilaskelma | E7: =_xlfn.XLOOKUP(C7,Laitokset!7:7,Laitokset!11:11) -> Ruotsin hallituksen selvityksestä | H7: Tiedot vuodelta | J7: =_xlfn.XLOOKUP(C7,Laitokset!7:7,Laitokset!3:3) -> 2024 | L7: =Laitokset!A61 -> Kiinteä OPEX | O7: =_xlfn.XLOOKUP(C$7,Laitokset!$7:$7,Laitokset!61:61) -> 0 | P7: =Laitokset!C61 -> EUR/MW/vuosi | R7: =Laitokset!A27 -> Suunnittelun aikataulu | T7: 1 | U7: =_xlfn.XLOOKUP($C$7,Laitokset!$7:$7,Laitokset!27:27) -> 0 | V7: =Laitokset!A43 -> Rakentamisaikataulutus | W7: 1 | X7: =_xlfn.XLOOKUP($C$7,Laitokset!$7:$7,Laitokset!43:43) -> 0.14285714
B8: Polttoaine | C8: =J11 -> Uraani | H8: Sijainti | J8: =_xlfn.XLOOKUP(C7,Laitokset!7:7,Laitokset!4:4) -> Ruotsi | L8: =Laitokset!A62 -> Muuttuva OPEX | O8: =_xlfn.XLOOKUP(C$7,Laitokset!$7:$7,Laitokset!62:62) -> 16.52 | P8: =Laitokset!C62 -> EUR/MWh | Q8: =IF(J12="Kyllä","Sis. pa-kustannukset!","") -> Sis. pa-kustannukset! | R8: =Laitokset!A28 -> (% käytetty vuodessa) | T8: 2 | U8: =_xlfn.XLOOKUP($C$7,Laitokset!$7:$7,Laitokset!28:28) -> 0 | V8: =Laitokset!A44 -> (% käytetty vuodessa) | W8: 2 | X8: =_xlfn.XLOOKUP($C$7,Laitokset!$7:$7,Laitokset!44:44) -> 0.14285714
B9: =H22 -> Suunnittelukustannukset | C9: Keski | H9: Rahayksikkö | J9: =_xlfn.XLOOKUP(C7,Laitokset!7:7,Laitokset!12:12) -> 2022 real EUR | L9: =Laitokset!A63 -> Vakuutus | O9: =_xlfn.XLOOKUP(C$7,Laitokset!$7:$7,Laitokset!63:63) -> 0 | P9: =Laitokset!C63 -> EUR/MW/vuosi | T9: 3 | U9: =_xlfn.XLOOKUP($C$7,Laitokset!$7:$7,Laitokset!29:29) -> 0 | W9: 3 | X9: =_xlfn.XLOOKUP($C$7,Laitokset!$7:$7,Laitokset!45:45) -> 0.14285714
B10: =H25 -> Suunnittelun kesto | C10: Keski | H10: =Laitokset!A5 -> Tekniikka | J10: =_xlfn.XLOOKUP(C7,Laitokset!7:7,Laitokset!5:5) -> Ydinreaktori, 1 250 MW | L10: =Laitokset!A64 -> Liittymis- ja muut kustannukset | O10: =_xlfn.XLOOKUP(C$7,Laitokset!$7:$7,Laitokset!64:64) -> 0 | P10: =Laitokset!C64 -> EUR/MW/vuosi | T10: 4 | U10: =_xlfn.XLOOKUP($C$7,Laitokset!$7:$7,Laitokset!30:30) -> 0 | W10: 4 | X10: =_xlfn.XLOOKUP($C$7,Laitokset!$7:$7,Laitokset!46:46) -> 0.14285714
B11: =H28 -> Rakentamiskustannukset | C11: Keski | H11: Polttoaine | J11: =_xlfn.XLOOKUP(C7,Laitokset!7:7,Laitokset!9:9) -> Uraani | L11: =Laitokset!A65 -> Lämmönmyyntisopimuksen kesto | O11: =_xlfn.XLOOKUP(C$7,Laitokset!$7:$7,Laitokset!65:65) -> 0 | P11: =Laitokset!C65 -> vuotta | T11: 5 | U11: =_xlfn.XLOOKUP($C$7,Laitokset!$7:$7,Laitokset!31:31) -> 0 | W11: 5 | X11: =_xlfn.XLOOKUP($C$7,Laitokset!$7:$7,Laitokset!47:47) -> 0.14285714
B12: =H31 -> Rakentamisaikataulu | C12: Pitkä | H12: Sisältyvätkö polttoainekustannukset OPEXiin? | J12: =_xlfn.XLOOKUP(C7,Laitokset!7:7,Laitokset!10:10,"") -> Kyllä | L12: =Laitokset!A66 -> Pääoman kustannus (WACC) | O12: =_xlfn.XLOOKUP(C$7,Laitokset!$7:$7,Laitokset!66:66)*100 -> 4 | P12: =Laitokset!C66 -> % | T12: 6 | U12: =_xlfn.XLOOKUP($C$7,Laitokset!$7:$7,Laitokset!32:32) -> 0 | W12: 6 | X12: =_xlfn.XLOOKUP($C$7,Laitokset!$7:$7,Laitokset!48:48) -> 0.14285714
B13: =H34 -> Infrastruktuurin hinta | C13: Keski | H13: Tekniikka vuodelta | J13: =_xlfn.XLOOKUP(C7,Laitokset!7:7,Laitokset!6:6) -> 2035 | L13: =Laitokset!A67 -> Jätemaksu | O13: =_xlfn.XLOOKUP(C$7,Laitokset!$7:$7,Laitokset!67:67)*100 -> 0 | P13: =Laitokset!C67 -> EUR/MWh | T13: 7 | U13: =_xlfn.XLOOKUP($C$7,Laitokset!$7:$7,Laitokset!33:33) -> 0 | W13: 7 | X13: =_xlfn.XLOOKUP($C$7,Laitokset!$7:$7,Laitokset!49:49) -> 0.14285714
B14: =L16 -> Purkukustannukset | C14: Keski | H14: =Laitokset!A13 -> Sähköntuotannon nimellisteho | J14: =_xlfn.XLOOKUP(C7,Laitokset!7:7,Laitokset!13:13) -> 1250 | K14: =Laitokset!C13 -> MWe | L14: =Laitokset!A68 -> Hiilen talteenotto | O14: =_xlfn.XLOOKUP(C$7,Laitokset!$7:$7,Laitokset!68:68)*100 -> 0 | P14: =Laitokset!C68 -> % | T14: 8 | U14: =_xlfn.XLOOKUP($C$7,Laitokset!$7:$7,Laitokset!34:34) -> 0 | W14: 8 | X14: =_xlfn.XLOOKUP($C$7,Laitokset!$7:$7,Laitokset!50:50) -> 0
B15: Polttoaineen hintaskenaario | C15: Keski | H15: =Laitokset!A14 -> Sähköntuotannon kapasiteettikerroin | J15: =_xlfn.XLOOKUP(C7,Laitokset!7:7,Laitokset!14:14)*100 -> 89 | K15: =Laitokset!C14 -> % | L15: =Laitokset!A69 -> Talteenoton hinta | O15: =_xlfn.XLOOKUP(C$7,Laitokset!$7:$7,Laitokset!69:69) -> 0 | P15: =Laitokset!C69 -> EUR/tCO2 | T15: 9 | U15: =_xlfn.XLOOKUP($C$7,Laitokset!$7:$7,Laitokset!35:35) -> 0 | W15: 9 | X15: =_xlfn.XLOOKUP($C$7,Laitokset!$7:$7,Laitokset!51:51) -> 0
B16: Polttoaineen päästötase | C16: Keski (IPCC) | H16: =Laitokset!A15 -> Sähköntuotannon hyötysuhde | J16: =_xlfn.XLOOKUP(C7,Laitokset!7:7,Laitokset!15:15)*100 -> 37 | K16: =Laitokset!C15 -> % | L16: =Laitokset!A70 -> Purkukustannukset | N16: =Laitokset!B70 -> Matala | O16: =_xlfn.XLOOKUP(C$7,Laitokset!$7:$7,Laitokset!70:70)*100 -> 0 | P16: =Laitokset!C70 -> % | T16: 10 | U16: =_xlfn.XLOOKUP($C$7,Laitokset!$7:$7,Laitokset!36:36) -> 0 | W16: 10 | X16: =_xlfn.XLOOKUP($C$7,Laitokset!$7:$7,Laitokset!52:52) -> 0
B17: Päästöoikeuden hintaskenaario | C17: Suomi, Ilmasto- ja energiastrategia (2021) | H17: =Laitokset!A16 -> Nimellistehon muutos | J17: =_xlfn.XLOOKUP(C7,Laitokset!7:7,Laitokset!16:16)*100 -> 0 | K17: =Laitokset!C16 -> %/vvuosi | N17: =Laitokset!B71 -> Keski | O17: =_xlfn.XLOOKUP(C$7,Laitokset!$7:$7,Laitokset!71:71)*100 -> 0 | P17: =Laitokset!C71 -> % | W17: 11 | X17: =_xlfn.XLOOKUP($C$7,Laitokset!$7:$7,Laitokset!53:53) -> 0
H18: =Laitokset!A17 -> Lämmöntuotannon kapasiteettikerroin | J18: =_xlfn.XLOOKUP(C7,Laitokset!7:7,Laitokset!17:17)*100 -> 0 | K18: =Laitokset!C17 -> % | N18: =Laitokset!B72 -> Korkea | O18: =_xlfn.XLOOKUP(C$7,Laitokset!$7:$7,Laitokset!72:72)*100 -> 0 | P18: =Laitokset!C72 -> % | W18: 12 | X18: =_xlfn.XLOOKUP($C$7,Laitokset!$7:$7,Laitokset!54:54) -> 0
B19: Projektin aloitusvuosi | C19: 2028 | H19: =Laitokset!A18 -> Yhteistuotannon hyötysuhde | J19: =_xlfn.XLOOKUP(C7,Laitokset!7:7,Laitokset!18:18)*100 -> 0 | K19: =Laitokset!C18 -> % | L19: =Laitokset!A73 -> Purkamisen viive | O19: =_xlfn.XLOOKUP(C$7,Laitokset!$7:$7,Laitokset!73:73) -> 0 | P19: =Laitokset!C73 -> vuotta | W19: 13 | X19: =_xlfn.XLOOKUP($C$7,Laitokset!$7:$7,Laitokset!55:55) -> 0
B20: =H13 -> Tekniikka vuodelta | C20: =J13 -> 2035 | H20: =Laitokset!A19 -> Käyttöikä | J20: =_xlfn.XLOOKUP(C7,Laitokset!7:7,Laitokset!19:19) -> 60 | K20: =Laitokset!C19 -> vuotta | W20: 14 | X20: =_xlfn.XLOOKUP($C$7,Laitokset!$7:$7,Laitokset!56:56) -> 0
B21: Rakentamisen aloitusvuosi | C21: =C19+_xlfn.XLOOKUP(C10,I25:I27,J25:J27) -> 2028 | H21: =Laitokset!A20 -> Regulaatio, luvitus, julkiset kuulemiset | J21: =_xlfn.XLOOKUP(C7,Laitokset!7:7,Laitokset!20:20) -> 0 | K21: =Laitokset!C20 -> EUR/kW | W21: 15 | X21: =_xlfn.XLOOKUP($C$7,Laitokset!$7:$7,Laitokset!57:57) -> 0
B22: Käyttöönottovuosi | C22: =C21+_xlfn.XLOOKUP(C12,I31:I33,J31:J33) -> 2036 | H22: =Laitokset!A21 -> Suunnittelukustannukset | I22: =Laitokset!B21 -> Matala | J22: =_xlfn.XLOOKUP(C$7,Laitokset!$7:$7,Laitokset!21:21) -> 0 | K22: =Laitokset!C21 -> EUR/kW
B23: Käytöstä poistovuosi | C23: =C22+J20 -> 2096 | I23: =Laitokset!B22 -> Keski | J23: =_xlfn.XLOOKUP(C$7,Laitokset!$7:$7,Laitokset!22:22) -> 0 | K23: =Laitokset!C22 -> EUR/kW
B24: Lämmön myyntisopimus päättyy | C24: =C22+O11 -> 2036 | I24: =Laitokset!B23 -> Korkea | J24: =_xlfn.XLOOKUP(C$7,Laitokset!$7:$7,Laitokset!23:23) -> 0 | K24: =Laitokset!C23 -> EUR/kW
E25: Muutokset | H25: =Laitokset!A24 -> Suunnittelun kesto | I25: =Laitokset!B24 -> Lyhyt | J25: =_xlfn.XLOOKUP(C$7,Laitokset!$7:$7,Laitokset!24:24) -> 0 | K25: =Laitokset!C24 -> vuotta
B26: =H14 -> Sähköntuotannon nimellisteho | C26: =_xlfn.XLOOKUP(C$7,Laitokset!$7:$7,Laitokset!13:13)+E26 -> 1250 | D26: =K14 -> MWe | E26: 0 | F26: Lisätään nimellistehoon | I26: =Laitokset!B25 -> Keski | J26: =_xlfn.XLOOKUP(C$7,Laitokset!$7:$7,Laitokset!25:25) -> 0 | K26: =Laitokset!C25 -> vuotta | U26: =IF(T46=$C$19,$B$19,IF(T46=$C$21,$B$21,IF(T46=$C$22,$B$22,IF(T46=$C$23,$B$23,IF(T46=$C$24,$B$24,""))))) | V26: =IF(U46=$C$19,$B$19,IF(U46=$C$21,$B$21,IF(U46=$C$22,$B$22,IF(U46=$C$23,$B$23,IF(U46=$C$24,$B$24,""))))) | W26: =IF(V46=$C$19,$B$19,IF(V46=$C$21,$B$21,IF(V46=$C$22,$B$22,IF(V46=$C$23,$B$23,IF(V46=$C$24,$B$24,""))))) | X26: =IF(W46=$C$19,$B$19,IF(W46=$C$21,$B$21,IF(W46=$C$22,$B$22,IF(W46=$C$23,$B$23,IF(W46=$C$24,$B$24,"")))))
B27: =H16 -> Sähköntuotannon hyötysuhde | C27: =_xlfn.XLOOKUP(C$7,Laitokset!$7:$7,Laitokset!15:15)+E27 -> 0.37 | E27: 0 | F27: Lisätään hyötysuhteeseen | I27: =Laitokset!B26 -> Pitkä | J27: =_xlfn.XLOOKUP(C$7,Laitokset!$7:$7,Laitokset!26:26) -> 0 | K27: =Laitokset!C26 -> vuotta | Q27: =IF(R46=$C$19,$B$19,IF(R46=$C$21,$B$21,IF(R46=$C$22,$B$22,IF(R46=$C$23,$B$23,IF(R46=$C$24,$B$24,""))))) -> Käyttöönottovuosi | R27: =IF(S46=$C$19,$B$19,IF(S46=$C$21,$B$21,IF(S46=$C$22,$B$22,IF(S46=$C$23,$B$23,IF(S46=$C$24,$B$24,""))))) | Z27: =IF(X46=$C$19,$B$19,IF(X46=$C$21,$B$21,IF(X46=$C$22,$B$22,IF(X46=$C$23,$B$23,IF(X46=$C$24,$B$24,""))))) | AA27: =IF(Y46=$C$19,$B$19,IF(Y46=$C$21,$B$21,IF(Y46=$C$22,$B$22,IF(Y46=$C$23,$B$23,IF(Y46=$C$24,$B$24,""))))) | AB27: =IF(Z46=$C$19,$B$19,IF(Z46=$C$21,$B$21,IF(Z46=$C$22,$B$22,IF(Z46=$C$23,$B$23,IF(Z46=$C$24,$B$24,""))))) | AC27: =IF(AA46=$C$19,$B$19,IF(AA46=$C$21,$B$21,IF(AA46=$C$22,$B$22,IF(AA46=$C$23,$B$23,IF(AA46=$C$24,$B$24,""))))) | AD27: =IF(AB46=$C$19,$B$19,IF(AB46=$C$21,$B$21,IF(AB46=$C$22,$B$22,IF(AB46=$C$23,$B$23,IF(AB46=$C$24,$B$24,""))))) | AE27: =IF(AC46=$C$19,$B$19,IF(AC46=$C$21,$B$21,IF(AC46=$C$22,$B$22,IF(AC46=$C$23,$B$23,IF(AC46=$C$24,$B$24,""))))) | AF27: =IF(AD46=$C$19,$B$19,IF(AD46=$C$21,$B$21,IF(AD46=$C$22,$B$22,IF(AD46=$C$23,$B$23,IF(AD46=$C$24,$B$24,""))))) | AG27: =IF(AE46=$C$19,$B$19,IF(AE46=$C$21,$B$21,IF(AE46=$C$22,$B$22,IF(AE46=$C$23,$B$23,IF(AE46=$C$24,$B$24,""))))) | ... AJ27: =IF(AH46=$C$19,$B$19,IF(AH46=$C$21,$B$21,IF(AH46=$C$22,$B$22,IF(AH46=$C$23,$B$23,IF(AH46=$C$24,$B$24,""))))) | AL27: =IF(AJ46=$C$19,$B$19,IF(AJ46=$C$21,$B$21,IF(AJ46=$C$22,$B$22,IF(AJ46=$C$23,$B$23,IF(AJ46=$C$24,$B$24,""))))) | AM27: =IF(AK46=$C$19,$B$19,IF(AK46=$C$21,$B$21,IF(AK46=$C$22,$B$22,IF(AK46=$C$23,$B$23,IF(AK46=$C$24,$B$24,""))))) | AN27: =IF(AL46=$C$19,$B$19,IF(AL46=$C$21,$B$21,IF(AL46=$C$22,$B$22,IF(AL46=$C$23,$B$23,IF(AL46=$C$24,$B$24,""))))) | AP27: =IF(AN46=$C$19,$B$19,IF(AN46=$C$21,$B$21,IF(AN46=$C$22,$B$22,IF(AN46=$C$23,$B$23,IF(AN46=$C$24,$B$24,""))))) | AQ27: =IF(AO46=$C$19,$B$19,IF(AO46=$C$21,$B$21,IF(AO46=$C$22,$B$22,IF(AO46=$C$23,$B$23,IF(AO46=$C$24,$B$24,""))))) | AR27: =IF(AP46=$C$19,$B$19,IF(AP46=$C$21,$B$21,IF(AP46=$C$22,$B$22,IF(AP46=$C$23,$B$23,IF(AP46=$C$24,$B$24,""))))) | AS27: =IF(AQ46=$C$19,$B$19,IF(AQ46=$C$21,$B$21,IF(AQ46=$C$22,$B$22,IF(AQ46=$C$23,$B$23,IF(AQ46=$C$24,$B$24,""))))) | AT27: =IF(AR46=$C$19,$B$19,IF(AR46=$C$21,$B$21,IF(AR46=$C$22,$B$22,IF(AR46=$C$23,$B$23,IF(AR46=$C$24,$B$24,""))))) | AV27: =IF(AT46=$C$19,$B$19,IF(AT46=$C$21,$B$21,IF(AT46=$C$22,$B$22,IF(AT46=$C$23,$B$23,IF(AT46=$C$24,$B$24,""))))) | AW27: =IF(AU46=$C$19,$B$19,IF(AU46=$C$21,$B$21,IF(AU46=$C$22,$B$22,IF(AU46=$C$23,$B$23,IF(AU46=$C$24,$B$24,""))))) | AX27: =IF(AV46=$C$19,$B$19,IF(AV46=$C$21,$B$21,IF(AV46=$C$22,$B$22,IF(AV46=$C$23,$B$23,IF(AV46=$C$24,$B$24,""))))) | AY27: =IF(AW46=$C$19,$B$19,IF(AW46=$C$21,$B$21,IF(AW46=$C$22,$B$22,IF(AW46=$C$23,$B$23,IF(AW46=$C$24,$B$24,""))))) | AZ27: =IF(AX46=$C$19,$B$19,IF(AX46=$C$21,$B$21,IF(AX46=$C$22,$B$22,IF(AX46=$C$23,$B$23,IF(AX46=$C$24,$B$24,""))))) | BA27: =IF(AY46=$C$19,$B$19,IF(AY46=$C$21,$B$21,IF(AY46=$C$22,$B$22,IF(AY46=$C$23,$B$23,IF(AY46=$C$24,$B$24,""))))) | BB27: =IF(AZ46=$C$19,$B$19,IF(AZ46=$C$21,$B$21,IF(AZ46=$C$22,$B$22,IF(AZ46=$C$23,$B$23,IF(AZ46=$C$24,$B$24,""))))) | BC27: =IF(BA46=$C$19,$B$19,IF(BA46=$C$21,$B$21,IF(BA46=$C$22,$B$22,IF(BA46=$C$23,$B$23,IF(BA46=$C$24,$B$24,""))))) | ... BU27: =IF(BS46=$C$19,$B$19,IF(BS46=$C$21,$B$21,IF(BS46=$C$22,$B$22,IF(BS46=$C$23,$B$23,IF(BS46=$C$24,$B$24,"")))))
B28: =H17 -> Nimellistehon muutos | C28: =J17/100+E28 -> 0 | D28: /vuosi | E28: 0 | F28: Lisätään muutosnopeuteen | H28: =Laitokset!A37 -> Rakentamiskustannukset | I28: =Laitokset!B37 -> Matala | J28: =_xlfn.XLOOKUP(C$7,Laitokset!$7:$7,Laitokset!37:37) -> 3272 | K28: =Laitokset!C37 -> EUR/kW
B29: =H15 -> Sähköntuotannon kapasiteettikerroin | C29: =J15/100+E29 -> 0.89 | E29: 0 | F29: Lisätään käyttöasteeseen | I29: =Laitokset!B38 -> Keski | J29: =_xlfn.XLOOKUP(C$7,Laitokset!$7:$7,Laitokset!38:38) -> 6544 | K29: =Laitokset!C38 -> EUR/kW
B30: Sähköntuotantoa vuodessa | C30: =8760*C29 -> 7796.4 | D30: h | I30: =Laitokset!B39 -> Korkea | J30: =_xlfn.XLOOKUP(C$7,Laitokset!$7:$7,Laitokset!39:39) -> 9816 | K30: =Laitokset!C39 -> EUR/kW
B31: =H18 -> Lämmöntuotannon kapasiteettikerroin | C31: =_xlfn.XLOOKUP(C$7,Laitokset!$7:$7,Laitokset!17:17)+E31 -> 0 | E31: 0 | F31: Lisätään käyttöasteeseen | H31: =Laitokset!A40 -> Rakentamisaikataulu | I31: =Laitokset!B40 -> Lyhyt | J31: =_xlfn.XLOOKUP(C$7,Laitokset!$7:$7,Laitokset!40:40) -> 5 | K31: =Laitokset!C40 -> vuotta
B32: Lämmöntuotantoa vuodessa | C32: =8760*C31 -> 0 | D32: h | I32: =Laitokset!B41 -> Keski | J32: =_xlfn.XLOOKUP(C$7,Laitokset!$7:$7,Laitokset!41:41) -> 7 | K32: =Laitokset!C41 -> vuotta
B33: =L12 -> Pääoman kustannus (WACC) | C33: =_xlfn.XLOOKUP(C$7,Laitokset!$7:$7,Laitokset!66:66)+E33 -> 0.05 | E33: 0.01 | F33: Lisätään pääoman kustannukseen | I33: =Laitokset!B42 -> Pitkä | J33: =_xlfn.XLOOKUP(C$7,Laitokset!$7:$7,Laitokset!42:42) -> 8 | K33: =Laitokset!C42 -> vuotta
H34: =Laitokset!A58 -> Infrastruktuurin hinta | I34: =Laitokset!B58 -> Matala | J34: =_xlfn.XLOOKUP(C$7,Laitokset!$7:$7,Laitokset!58:58) -> 0 | K34: =Laitokset!C58 -> EUR
I35: =Laitokset!B59 -> Keski | J35: =_xlfn.XLOOKUP(C$7,Laitokset!$7:$7,Laitokset!59:59) -> 0 | K35: =Laitokset!C59 -> EUR
I36: =Laitokset!B60 -> Korkea | J36: =_xlfn.XLOOKUP(C$7,Laitokset!$7:$7,Laitokset!60:60) -> 0 | K36: =Laitokset!C60 -> EUR
B37: Tulokset: LCOE | C37: =_xlfn.CONCAT(LEFT(J9,4)," EUR") -> 2022 EUR | E37: 2023 EUR
B38: Sähkön tasoitettu tuotantokustannus | C38: =SUM(C40:C48) -> 71.737104 | D38: /MWhe | E38: =C38*1.062 -> 76.184805 | H38: Polttoaine- ja päästömaksut
B39: josta | J39: =C19 -> 2028 | K39: =J39+1 -> 2029 | L39: =K39+1 -> 2030 | M39: =L39+1 -> 2031 | N39: =M39+1 -> 2032 | O39: =N39+1 -> 2033 | P39: =O39+1 -> 2034 | Q39: =P39+1 -> 2035 | R39: =Q39+1 -> 2036 | ... BS39: =BR39+1 -> 2089
B40: Suunnittelukustannukset | C40: =H56 -> 0 | D40: /MWhe | E40: =C40*1.062 -> 0 | H40: =_xlfn.CONCAT("Polttoaine: ",J11) -> Polttoaine: Uraani | I40: =IF(J12="Kyllä","Kustannukset sis. OPEXiin",I129) -> Kustannukset sis. OPEXiin | J40: =_xlfn.XLOOKUP(J$39,$J$128:$DF$128,$J129:$DF129)*IF($J$12="Kyllä",0,1) -> 0 | K40: =_xlfn.XLOOKUP(K$39,$J$128:$DF$128,$J129:$DF129)*IF($J$12="Kyllä",0,1) -> 0 | L40: =_xlfn.XLOOKUP(L$39,$J$128:$DF$128,$J129:$DF129)*IF($J$12="Kyllä",0,1) -> 0 | M40: =_xlfn.XLOOKUP(M$39,$J$128:$DF$128,$J129:$DF129)*IF($J$12="Kyllä",0,1) -> 0 | N40: =_xlfn.XLOOKUP(N$39,$J$128:$DF$128,$J129:$DF129)*IF($J$12="Kyllä",0,1) -> 0 | O40: =_xlfn.XLOOKUP(O$39,$J$128:$DF$128,$J129:$DF129)*IF($J$12="Kyllä",0,1) -> 0 | P40: =_xlfn.XLOOKUP(P$39,$J$128:$DF$128,$J129:$DF129)*IF($J$12="Kyllä",0,1) -> 0 | Q40: =_xlfn.XLOOKUP(Q$39,$J$128:$DF$128,$J129:$DF129)*IF($J$12="Kyllä",0,1) -> 0 | ... BS40: =_xlfn.XLOOKUP(BS$39,$J$128:$DF$128,$J129:$DF129)*IF($J$12="Kyllä",0,1) -> 0
B41: Pääomakustannukset (rakennuskustannukset) | C41: =H65 -> 55.217104 | D41: /MWhe | E41: =C41*1.062 -> 58.640565 | H41: Polttoaineen päästötase | I41: kgCO2e/MWh | J41: =_xlfn.XLOOKUP(J$39,$J$128:$DF$128,$J130:$DF130) -> 0 | K41: =_xlfn.XLOOKUP(K$39,$J$128:$DF$128,$J130:$DF130) -> 0 | L41: =_xlfn.XLOOKUP(L$39,$J$128:$DF$128,$J130:$DF130) -> 0 | M41: =_xlfn.XLOOKUP(M$39,$J$128:$DF$128,$J130:$DF130) -> 0 | N41: =_xlfn.XLOOKUP(N$39,$J$128:$DF$128,$J130:$DF130) -> 0 | O41: =_xlfn.XLOOKUP(O$39,$J$128:$DF$128,$J130:$DF130) -> 0 | P41: =_xlfn.XLOOKUP(P$39,$J$128:$DF$128,$J130:$DF130) -> 0 | Q41: =_xlfn.XLOOKUP(Q$39,$J$128:$DF$128,$J130:$DF130) -> 0 | ... BS41: =_xlfn.XLOOKUP(BS$39,$J$128:$DF$128,$J130:$DF130) -> 0
...

Sheet Laitokset
A1: Vuodelta 2023. Hinnat 2022 EUR.
A2: Lähde | D2: https://www.gov.uk/government/publications/electricity-generation-costs-2023 | E2: https://www.gov.uk/government/publications/electricity-generation-costs-2024 | F2: https://www.gov.uk/government/publications/electricity-generation-costs-2025 | G2: https://www.gov.uk/government/publications/electricity-generation-costs-2026 | H2: https://www.gov.uk/government/publications/electricity-generation-costs-2027 | I2: https://www.gov.uk/government/publications/electricity-generation-costs-2028 | J2: https://www.gov.uk/government/publications/electricity-generation-costs-2029 | K2: https://www.gov.uk/government/publications/electricity-generation-costs-2030 | L2: https://www.gov.uk/government/publications/electricity-generation-costs-2031 | M2: https://www.gov.uk/government/publications/electricity-generation-costs-2032 | N2: https://www.gov.uk/government/publications/electricity-generation-costs-2033 | O2: https://www.gov.uk/government/publications/electricity-generation-costs-2034 | P2: https://www.gov.uk/government/publications/electricity-generation-costs-2035 | Q2: https://www.gov.uk/government/publications/electricity-generation-costs-2036 | R2: https://www.gov.uk/government/publications/electricity-generation-costs-2037 | S2: https://www.gov.uk/government/publications/electricity-generation-costs-2038 | T2: https://www.gov.uk/government/publications/electricity-generation-costs-2039 | U2: https://www.gov.uk/government/publications/electricity-generation-costs-2040 | V2: https://www.gov.uk/government/publications/electricity-generation-costs-2041 | W2: https://www.gov.uk/government/publications/electricity-generation-costs-2042 | X2: https://www.gov.uk/government/publications/electricity-generation-costs-2043 | Y2: https://www.gov.uk/government/publications/electricity-generation-costs-2044 | Z2: https://www.gov.uk/government/publications/electricity-generation-costs-2045 | AA2: https://www.gov.uk/government/publications/electricity-generation-costs-2046 | AB2: https://www.gov.uk/government/publications/electricity-generation-costs-2047 | AC2: https://www.gov.uk/government/publications/electricity-generation-costs-2048 | AD2: https://www.gov.uk/government/publications/electricity-generation-costs-2049 | AE2: https://www.gov.uk/government/publications/electricity-generation-costs-2050 | AF2: https://www.gov.uk/government/publications/electricity-generation-costs-2051 | AG2: https://www.gov.uk/government/publications/electricity-generation-costs-2052 | AH2: https://www.gov.uk/government/publications/electricity-generation-costs-2053 | AI2: https://www.gov.uk/government/publications/electricity-generation-costs-2054 | AJ2: https://www.gov.uk/government/publications/electricity-generation-costs-2055 | AK2: https://www.gov.uk/government/publications/electricity-generation-costs-2056 | AL2: https://www.gov.uk/government/publications/electricity-generation-costs-2057 | AM2: https://www.gov.uk/government/publications/electricity-generation-costs-2058 | AN2: https://www.gov.uk/government/publications/electricity-generation-costs-2059 | AO2: https://www.gov.uk/government/publications/electricity-generation-costs-2060 | AP2: https://www.gov.uk/government/publications/electricity-generation-costs-2061 | AQ2: https://www.gov.uk/government/publications/electricity-generation-costs-2062 | AR2: https://www.gov.uk/government/publications/electricity-generation-costs-2063 | AS2: https://www.gov.uk/government/publications/electricity-generation-costs-2064 | AT2: https://www.gov.uk/government/publications/electricity-generation-costs-2065 | AU2: https://www.gov.uk/government/publications/electricity-generation-costs-2066 | AV2: https://www.gov.uk/government/publications/electricity-generation-costs-2067 | AW2: https://www.gov.uk/government/publications/electricity-generation-costs-2068 | AX2: https://www.gov.uk/government/publications/electricity-generation-costs-2069 | AY2: https://www.gov.uk/government/publications/electricity-generation-costs-2070 | AZ2: https://www.gov.uk/government/publications/electricity-generation-costs-2071 | BA2: https://www.gov.uk/government/publications/electricity-generation-costs-2072 | BB2: https://www.gov.uk/government/publications/electricity-generation-costs-2073 | BC2: https://www.gov.uk/government/publications/electricity-generation-costs-2074 | BD2: https://www.gov.uk/government/publications/electricity-generation-costs-2075 | BE2: https://www.gov.uk/government/publications/electricity-generation-costs-2076 | BF2: https://www.gov.uk/government/publications/electricity-generation-costs-2077 | BG2: https://www.gov.uk/government/publications/electricity-generation-costs-2078 | BH2: https://www.gov.uk/government/publications/electricity-generation-costs-2079 | BI2: https://www.gov.uk/government/publications/electricity-generation-costs-2080 | BJ2: https://www.gov.uk/government/publications/electricity-generation-costs-2081 | BK2: https://www.gov.uk/government/publications/electricity-generation-costs-2082 | BL2: https://www.gov.uk/government/publications/electricity-generation-costs-2083 | BM2: https://www.gov.uk/government/publications/electricity-generation-costs-2084 | BN2: https://www.gov.uk/government/publications/electricity-generation-costs-2085 | BO2: https://www.gov.uk/government/publications/electricity-generation-costs-2086 | BP2: https://www.gov.uk/government/publications/electricity-generation-costs-2087 | BQ2: https://www.gov.uk/government/publications/electricity-generation-costs-2088 | BR2: https://www.gov.uk/government/publications/electricity-generation-costs-2089 | BS2: https://www.gov.uk/government/publications/electricity-generation-costs-2090 | BT2: https://www.gov.uk/government/publications/electricity-generation-costs-2091 | BU2: https://www.gov.uk/government/publications/electricity-generation-costs-2092 | BV2: https://www.gov.uk/government/publications/electricity-generation-costs-2093 | BW2: https://www.gov.uk/government/publications/electricity-generation-costs-2094 | BX2: https://www.gov.uk/government/publications/electricity-generation-costs-2095 | BY2: https://www.gov.uk/government/publications/electricity-generation-costs-2096 | BZ2: https://www.gov.uk/government/publications/electricity-generation-costs-2097 | CA2: https://www.gov.uk/government/publications/electricity-generation-costs-2098 | CB2: https://www.gov.uk/government/publications/electricity-generation-costs-2099 | CC2: https://www.gov.uk/government/publications/electricity-generation-costs-2100 | CD2: https://www.gov.uk/government/publications/electricity-generation-costs-2101 | CE2: https://www.gov.uk/government/publications/electricity-generation-costs-2102 | CF2: https://www.gov.uk/government/publications/electricity-generation-costs-2103 | CG2: https://www.gov.uk/government/publications/electricity-generation-costs-2104 | CH2: https://www.gov.uk/government/publications/electricity-generation-costs-2105 | CI2: https://www.gov.uk/government/publications/electricity-generation-costs-2106 | CJ2: https://www.gov.uk/government/publications/electricity-generation-costs-2107 | CK2: https://www.gov.uk/government/publications/electricity-generation-costs-2108 | CL2: https://www.gov.uk/government/publications/electricity-generation-costs-2109 | CM2: https://www.gov.uk/government/publications/electricity-generation-costs-2110 | CN2: Way, R., Ives, M. C., Mealy, P., & Farmer, J. D. (2022). Empirically grounded technology forecasts and the energy transition: Supplementary material. Joule, 6(9), 2057–2082. https://doi.org/10.1016/j.joule.2022.08.009 | CO2: Way, R., Ives, M. C., Mealy, P., & Farmer, J. D. (2022). Empirically grounded technology forecasts and the energy transition: Supplementary material. Joule, 6(9), 2057–2082. https://doi.org/10.1016/j.joule.2022.08.009 | CP2: Way, R., Ives, M. C., Mealy, P., & Farmer, J. D. (2022). Empirically grounded technology forecasts and the energy transition: Supplementary material. Joule, 6(9), 2057–2082. https://doi.org/10.1016/j.joule.2022.08.009 | CQ2: https://www.gov.uk/government/publications/electricity-generation-costs-2111 | CR2: https://www.gov.uk/government/publications/electricity-generation-costs-2112 | CS2: https://www.gov.uk/government/publications/electricity-generation-costs-2113 | CT2: https://www.gov.uk/government/publications/electricity-generation-costs-2114 | CU2: https://www.gov.uk/government/publications/electricity-generation-costs-2115 | CV2: https://www.gov.uk/government/publications/electricity-generation-costs-2116 | CW2: https://www.gov.uk/government/publications/electricity-generation-costs-2117 | CX2: https://www.gov.uk/government/publications/electricity-generation-costs-2118 | CY2: https://www.gov.uk/government/publications/electricity-generation-costs-2119 | CZ2: https://www.gov.uk/government/publications/electricity-generation-costs-2120 | DA2: https://www.gov.uk/government/publications/electricity-generation-costs-2121 | DB2: https://www.gov.uk/government/publications/electricity-generation-costs-2122 | DC2: https://www.gov.uk/government/publications/electricity-generation-costs-2123 | DD2: https://www.gov.uk/government/publications/electricity-generation-costs-2124 | DE2: https://www.gov.uk/government/publications/electricity-generation-costs-2125 | DF2: https://www.gov.uk/government/publications/electricity-generation-costs-2126 | DG2: https://www.gov.uk/government/publications/electricity-generation-costs-2127 | DH2: https://www.gov.uk/government/publications/electricity-generation-costs-2128 | DI2: https://www.gov.uk/government/publications/electricity-generation-costs-2129 | DJ2: https://www.gov.uk/government/publications/electricity-generation-costs-2130 | DK2: https://www.gov.uk/government/publications/electricity-generation-costs-2131 | DL2: https://www.gov.uk/government/publications/electricity-generation-costs-2132 | DM2: https://www.gov.uk/government/publications/electricity-generation-costs-2133 | DN2: https://www.gov.uk/government/publications/electricity-generation-costs-2134 | DO2: https://www.gov.uk/government/publications/electricity-generation-costs-2135 | DP2: https://www.gov.uk/government/publications/electricity-generation-costs-2136 | DQ2: https://www.gov.uk/government/publications/electricity-generation-costs-2137 | DR2: https://www.gov.uk/government/publications/electricity-generation-costs-2138 | DS2: https://www.gov.uk/government/publications/electricity-generation-costs-2139 | DT2: https://www.gov.uk/government/publications/electricity-generation-costs-2140 | DU2: https://www.gov.uk/government/publications/electricity-generation-costs-2141 | DV2: https://www.gov.uk/government/publications/electricity-generation-costs-2142 | DW2: https://www.gov.uk/government/publications/electricity-generation-costs-2143 | DX2: https://www.gov.uk/government/publications/electricity-generation-costs-2144 | DY2: https://www.gov.uk/government/publications/electricity-generation-costs-2145 | DZ2: https://www.gov.uk/government/publications/electricity-generation-costs-2146 | EA2: https://www.gov.uk/government/publications/electricity-generation-costs-2147 | EB2: https://www.gov.uk/government/publications/electricity-generation-costs-2148 | EC2: https://www.gov.uk/government/publications/electricity-generation-costs-2149 | ED2: https://www.gov.uk/government/publications/electricity-generation-costs-2150 | EE2: https://www.gov.uk/government/publications/electricity-generation-costs-2151 | EF2: https://www.gov.uk/government/publications/electricity-generation-costs-2152 | EG2: https://www.gov.uk/government/publications/electricity-generation-costs-2153 | EH2: https://www.gov.uk/government/publications/electricity-generation-costs-2154 | EI2: https://www.gov.uk/government/publications/electricity-generation-costs-2155 | EJ2: https://www.gov.uk/government/publications/electricity-generation-costs-2156 | EK2: https://www.gov.uk/government/publications/electricity-generation-costs-2157 | EL2: https://www.gov.uk/government/publications/electricity-generation-costs-2158 | EM2: https://www.gov.uk/government/publications/electricity-generation-costs-2159 | EN2: https://www.gov.uk/government/publications/electricity-generation-costs-2160 | EO2: https://www.gov.uk/government/publications/electricity-generation-costs-2161 | EP2: https://www.gov.uk/government/publications/electricity-generation-costs-2162 | EQ2: https://www.gov.uk/government/publications/electricity-generation-costs-2163 | ER2: https://www.gov.uk/government/publications/electricity-generation-costs-2164 | ES2: https://www.gov.uk/government/publications/electricity-generation-costs-2165 | ET2: https://www.gov.uk/government/publications/electricity-generation-costs-2166 | EU2: https://www.gov.uk/government/publications/electricity-generation-costs-2167 | EV2: https://www.gov.uk/government/publications/electricity-generation-costs-2168 | EW2: https://www.gov.uk/government/publications/electricity-generation-costs-2169 | EX2: https://www.gov.uk/government/publications/electricity-generation-costs-2170 | EY2: https://www.gov.uk/government/publications/electricity-generation-costs-2171 | EZ2: https://www.gov.uk/government/publications/electricity-generation-costs-2172 | FA2: https://www.gov.uk/government/publications/electricity-generation-costs-2173 | FB2: https://www.gov.uk/government/publications/electricity-generation-costs-2174 | FC2: https://www.gov.uk/government/publications/electricity-generation-costs-2175 | FD2: https://www.gov.uk/government/publications/electricity-generation-costs-2176 | FE2: https://www.gov.uk/government/publications/electricity-generation-costs-2177 | FF2: https://www.gov.uk/government/publications/electricity-generation-costs-2178 | FG2: https://www.gov.uk/government/publications/electricity-generation-costs-2179 | FH2: https://www.gov.uk/government/publications/electricity-generation-costs-2180 | FI2: https://www.gov.uk/government/publications/electricity-generation-costs-2181 | FJ2: https://www.gov.uk/government/publications/electricity-generation-costs-2182 | FK2: Construction costs from Deutsche Welle via Helsingin Sanomat, 1.2.2023. | FL2: Vakkilainen2017
A3: Tiedot vuodelta | D3: 2021 | E3: 2021 | F3: 2021 | G3: 2021 | H3: 2021 | I3: 2021 | J3: 2021 | K3: 2021 | L3: 2021 | M3: 2021 | N3: 2021 | O3: 2021 | P3: 2021 | Q3: 2021 | R3: 2021 | S3: 2021 | T3: 2021 | U3: 2021 | V3: 2021 | W3: 2021 | X3: 2021 | Y3: 2021 | Z3: 2021 | AA3: 2021 | AB3: 2021 | AC3: 2021 | AD3: 2021 | AE3: 2021 | AF3: 2021 | AG3: 2021 | AH3: 2021 | AI3: 2021 | AJ3: 2021 | AK3: 2021 | AL3: 2021 | AM3: 2021 | AN3: 2021 | AO3: 2021 | AP3: 2021 | AQ3: 2021 | AR3: 2021 | AS3: 2021 | AT3: 2021 | AU3: 2021 | AV3: 2021 | AW3: 2021 | AX3: 2021 | AY3: 2021 | AZ3: 2021 | BA3: 2021 | BB3: 2021 | BC3: 2021 | BD3: 2021 | BE3: 2021 | BF3: 2021 | BG3: 2021 | BH3: 2021 | BI3: 2021 | BJ3: 2021 | BK3: 2021 | BL3: 2021 | BM3: 2021 | BN3: 2021 | BO3: 2021 | BP3: 2021 | BQ3: 2021 | BR3: 2021 | BS3: 2021 | BT3: 2021 | BU3: 2021 | BV3: 2021 | BW3: 2021 | BX3: 2021 | BY3: 2021 | BZ3: 2021 | CA3: 2021 | CB3: 2021 | CC3: 2021 | CD3: 2021 | CE3: 2021 | CF3: 2021 | CG3: 2021 | CH3: 2021 | CI3: 2021 | CJ3: 2021 | CK3: 2021 | CL3: 2021 | CM3: 2021 | CQ3: 2021 | CR3: 2021 | CS3: 2021 | CT3: 2021 | CU3: 2021 | CV3: 2021 | CW3: 2021 | CX3: 2021 | CY3: 2021 | CZ3: 2021 | DA3: 2021 | DB3: 2021 | DC3: 2021 | DD3: 2021 | DE3: 2021 | DF3: 2021 | DG3: 2021 | DH3: 2021 | DI3: 2021 | DJ3: 2021 | DK3: 2021 | DL3: 2021 | DM3: 2021 | DN3: 2021 | DO3: 2021 | DP3: 2021 | DQ3: 2021 | DR3: 2021 | DS3: 2021 | DT3: 2021 | DU3: 2021 | DV3: 2021 | DW3: 2021 | DX3: 2021 | DY3: 2021 | DZ3: 2021 | EA3: 2021 | EB3: 2021 | EC3: 2021 | ED3: 2021 | EE3: 2021 | EF3: 2021 | EG3: 2021 | EH3: 2021 | EI3: 2021 | EJ3: 2021 | EK3: 2021 | EL3: 2021 | EM3: 2021 | EN3: 2021 | EO3: 2021 | EP3: 2021 | EQ3: 2021 | ER3: 2021 | ES3: 2021 | ET3: 2021 | EU3: 2021 | EV3: 2021 | EW3: 2021 | EX3: 2021 | EY3: 2021 | EZ3: 2021 | FA3: 2021 | FB3: 2021 | FC3: 2021 | FD3: 2021 | FE3: 2021 | FF3: 2021 | FG3: 2021 | FH3: 2021 | FI3: 2021 | FJ3: 2021 | FK3: 2022 | FL3: 2017 | FM3: 2017 | FN3: 2017 | FO3: 2024
A4: Sijainti | D4: Iso-Britannia | E4: Iso-Britannia | F4: Iso-Britannia | G4: Iso-Britannia | H4: Iso-Britannia | I4: Iso-Britannia | J4: Iso-Britannia | K4: Iso-Britannia | L4: Iso-Britannia | M4: Iso-Britannia | N4: Iso-Britannia | O4: Iso-Britannia | P4: Iso-Britannia | Q4: Iso-Britannia | R4: Iso-Britannia | S4: Iso-Britannia | T4: Iso-Britannia | U4: Iso-Britannia | V4: Iso-Britannia | W4: Iso-Britannia | X4: Iso-Britannia | Y4: Iso-Britannia | Z4: Iso-Britannia | AA4: Iso-Britannia | AB4: Iso-Britannia | AC4: Iso-Britannia | AD4: Iso-Britannia | AE4: Iso-Britannia | AF4: Iso-Britannia | AG4: Iso-Britannia | AH4: Iso-Britannia | AI4: Iso-Britannia | AJ4: Iso-Britannia | AK4: Iso-Britannia | AL4: Iso-Britannia | AM4: Iso-Britannia | AN4: Iso-Britannia | AO4: Iso-Britannia | AP4: Iso-Britannia | AQ4: Iso-Britannia | AR4: Iso-Britannia | AS4: Iso-Britannia | AT4: Iso-Britannia | AU4: Iso-Britannia | AV4: Iso-Britannia | AW4: Iso-Britannia | AX4: Iso-Britannia | AY4: Iso-Britannia | AZ4: Iso-Britannia | BA4: Iso-Britannia | BB4: Iso-Britannia | BC4: Iso-Britannia | BD4: Iso-Britannia | BE4: Iso-Britannia | BF4: Iso-Britannia | BG4: Iso-Britannia | BH4: Iso-Britannia | BI4: Iso-Britannia | BJ4: Iso-Britannia | BK4: Iso-Britannia | BL4: Iso-Britannia | BM4: Iso-Britannia | BN4: Iso-Britannia | BO4: Iso-Britannia | BP4: Iso-Britannia | BQ4: Iso-Britannia | BR4: Iso-Britannia | BS4: Iso-Britannia | BT4: Iso-Britannia | BU4: Iso-Britannia | BV4: Iso-Britannia | BW4: Iso-Britannia | BX4: Iso-Britannia | BY4: Iso-Britannia | BZ4: Iso-Britannia | CA4: Iso-Britannia | CB4: Iso-Britannia | CC4: Iso-Britannia | CD4: Iso-Britannia | CE4: Iso-Britannia | CF4: Iso-Britannia | CG4: Iso-Britannia | CH4: Iso-Britannia | CI4: Iso-Britannia | CJ4: Iso-Britannia | CK4: Iso-Britannia | CL4: Iso-Britannia | CM4: Iso-Britannia | CN4: Maailma | CO4: Maailma | CP4: Maailma | CQ4: Iso-Britannia | CR4: Iso-Britannia | CS4: Iso-Britannia | CT4: Iso-Britannia | CU4: Iso-Britannia | CV4: Iso-Britannia | CW4: Iso-Britannia | CX4: Iso-Britannia | CY4: Iso-Britannia | CZ4: Iso-Britannia | DA4: Iso-Britannia | DB4: Iso-Britannia | DC4: Iso-Britannia | DD4: Iso-Britannia | DE4: Iso-Britannia | DF4: Iso-Britannia | DG4: Iso-Britannia | DH4: Iso-Britannia | DI4: Iso-Britannia | DJ4: Iso-Britannia | DK4: Iso-Britannia | DL4: Iso-Britannia | DM4: Iso-Britannia | DN4: Iso-Britannia | DO4: Iso-Britannia | DP4: Iso-Britannia | DQ4: Iso-Britannia | DR4: Iso-Britannia | DS4: Iso-Britannia | DT4: Iso-Britannia | DU4: Iso-Britannia | DV4: Iso-Britannia | DW4: Iso-Britannia | DX4: Iso-Britannia | DY4: Iso-Britannia | DZ4: Iso-Britannia | EA4: Iso-Britannia | EB4: Iso-Britannia | EC4: Iso-Britannia | ED4: Iso-Britannia | EE4: Iso-Britannia | EF4: Iso-Britannia | EG4: Iso-Britannia | EH4: Iso-Britannia | EI4: Iso-Britannia | EJ4: Iso-Britannia | EK4: Iso-Britannia | EL4: Iso-Britannia | EM4: Iso-Britannia | EN4: Iso-Britannia | EO4: Iso-Britannia | EP4: Iso-Britannia | EQ4: Iso-Britannia | ER4: Iso-Britannia | ES4: Iso-Britannia | ET4: Iso-Britannia | EU4: Iso-Britannia | EV4: Iso-Britannia | EW4: Iso-Britannia | EX4: Iso-Britannia | EY4: Iso-Britannia | EZ4: Iso-Britannia | FA4: Iso-Britannia | FB4: Iso-Britannia | FC4: Iso-Britannia | FD4: Iso-Britannia | FE4: Iso-Britannia | FF4: Iso-Britannia | FG4: Iso-Britannia | FH4: Iso-Britannia | FI4: Iso-Britannia | FJ4: Iso-Britannia | FK4: Puola | FL4: Suomi | FM4: Suomi | FN4: Suomi | FO4: Ruotsi
A5: Tekniikka | D5: CCGT H Class | E5: CCGT H Class | F5: CCGT H Class | G5: CCGT H Class | H5: CCGT CHP mode | I5: CCGT CHP mode | J5: CCGT CHP mode | K5: CCGT CHP mode | L5: OCGT 600MW 500 hr | M5: OCGT 600MW 500 hr | N5: OCGT 600MW 500 hr | O5: OCGT 600MW 500 hr | P5: OCGT 400MW 500 hr | Q5: OCGT 400MW 500 hr | R5: OCGT 400MW 500 hr | S5: OCGT 400MW 500 hr | T5: OCGT 300MW 500 hr | U5: OCGT 300MW 500 hr | V5: OCGT 300MW 500 hr | W5: OCGT 300MW 500 hr | X5: OCGT 299MW 500 hr | Y5: OCGT 299MW 500 hr | Z5: OCGT 299MW 500 hr | AA5: OCGT 299MW 500 hr | AB5: OCGT 100MW 500 hr | AC5: OCGT 100MW 500 hr | AD5: OCGT 100MW 500 hr | AE5: OCGT 100MW 500 hr | AF5: OCGT 600MW 2000 hr | AG5: OCGT 600MW 2000 hr | AH5: OCGT 600MW 2000 hr | AI5: OCGT 600MW 2000 hr | AJ5: OCGT 400MW 2000 hr | AK5: OCGT 400MW 2000 hr | AL5: OCGT 400MW 2000 hr | AM5: OCGT 400MW 2000 hr | AN5: OCGT 300MW 2000 hr | AO5: OCGT 300MW 2000 hr | AP5: OCGT 300MW 2000 hr | AQ5: OCGT 300MW 2000 hr | AR5: OCGT 299MW 2000 hr | AS5: OCGT 299MW 2000 hr | AT5: OCGT 299MW 2000 hr | AU5: OCGT 299MW 2000 hr | AV5: OCGT 100MW 2000 hr | AW5: OCGT 100MW 2000 hr | AX5: OCGT 100MW 2000 hr | AY5: OCGT 100MW 2000 hr | AZ5: Recip Diesel 2000 hr | BA5: Recip Diesel 2000 hr | BB5: Recip Diesel 2000 hr | BC5: Recip Diesel 2000 hr | BD5: Recip Diesel 500 hrs | BE5: Recip Diesel 500 hrs | BF5: Recip Diesel 500 hrs | BG5: Recip Diesel 500 hrs | BH5: Recip Diesel 90 hrs | BI5: Recip Diesel 90 hrs | BJ5: Recip Diesel 90 hrs | BK5: Recip Diesel 90 hrs | BL5: Recip Gas 2000 hr | BM5: Recip Gas 2000 hr | BN5: Recip Gas 2000 hr | BO5: Recip Gas 2000 hr | BP5: Recip Gas 500 hrs | BQ5: Recip Gas 500 hrs | BR5: Recip Gas 500 hrs | BS5: Recip Gas 500 hrs | BT5: Dedicated Biomass | BU5: Dedicated Biomass | BV5: Dedicated Biomass | BW5: Dedicated Biomass | BX5: Biomass CHP | BY5: Biomass CHP | BZ5: Biomass CHP | CA5: Biomass CHP | CB5: Onshore Wind | CC5: Onshore Wind | CD5: Onshore Wind | CE5: Onshore Wind | CF5: Offshore Wind | CG5: Offshore Wind | CH5: Offshore Wind | CI5: Offshore Wind | CJ5: Large-scale Solar | CK5: Large-scale Solar | CL5: Large-scale Solar | CM5: Large-scale Solar | CN5: Teollinen aurinkosähkö, lattiahinta 2000 (Way2022b) | CO5: Teollinen aurinkosähkö, lattiahinta 2005 (Way2022b) | CP5: Teollinen aurinkosähkö, lattiahinta 2015 (Way2022b) | CQ5: Solar PV 10-50kW | CR5: Solar PV 10-50kW | CS5: Solar PV 10-50kW | CT5: Solar PV 10-50kW | CU5: Solar PV 4-10kW | CV5: Solar PV 4-10kW | CW5: Solar PV 4-10kW | CX5: Solar PV 4-10kW | CY5: Solar PV <4kW | CZ5: Solar PV <4kW | DA5: Solar PV <4kW | DB5: Solar PV <4kW | DC5: EfW | DD5: EfW | DE5: EfW | DF5: EfW | DG5: EfW CHP | DH5: EfW CHP | DI5: EfW CHP | DJ5: EfW CHP | DK5: AD | DL5: AD | DM5: AD | DN5: AD | DO5: AD CHP | DP5: AD CHP | DQ5: AD CHP | DR5: AD CHP | DS5: ACT Standard | DT5: ACT Standard | DU5: ACT Standard | DV5: ACT Standard | DW5: ACT Advanced | DX5: ACT Advanced | DY5: ACT Advanced | DZ5: ACT Advanced | EA5: ACT CHP | EB5: ACT CHP | EC5: ACT CHP | ED5: ACT CHP | EE5: Landfill gas | EF5: Landfill gas | EG5: Landfill gas | EH5: Landfill gas | EI5: Sewage gas | EJ5: Sewage gas | EK5: Sewage gas | EL5: Sewage gas | EM5: Geothermal CHP | EN5: Geothermal CHP | EO5: Geothermal CHP | EP5: Geothermal CHP | EQ5: Hydro Large Storage | ER5: Hydro Large Storage | ES5: Hydro Large Storage | ET5: Hydro Large Storage | EU5: Hydro 516MW | EV5: Hydro 516MW | EW5: Hydro 516MW | EX5: Hydro 516MW | EY5: Wave | EZ5: Wave | FA5: Wave | FB5: Wave | FC5: Hydrogen CCGT (FOAK) | FD5: Hydrogen CCGT (FOAK) | FE5: Hydrogen CCGT (FOAK) | FF5: Hydrogen CCGT (FOAK) | FG5: Hydrogen CCGT (NOAK) | FH5: Hydrogen CCGT (NOAK) | FI5: Hydrogen CCGT (NOAK) | FJ5: Hydrogen CCGT (NOAK) | FK5: AP1000 Nuclear | FL5: EPR-reaktori | FM5: Tuulivoima | FN5: Kaasu | FO5: Ydinreaktori, 1 250 MW
A6: Käyttöönottovuosi | D6: 2025 | E6: 2030 | F6: 2035 | G6: 2040 | H6: 2025 | I6: 2030 | J6: 2035 | K6: 2040 | L6: 2025 | M6: 2030 | N6: 2035 | O6: 2040 | P6: 2025 | Q6: 2030 | R6: 2035 | S6: 2040 | T6: 2025 | U6: 2030 | V6: 2035 | W6: 2040 | X6: 2025 | Y6: 2030 | Z6: 2035 | AA6: 2040 | AB6: 2025 | AC6: 2030 | AD6: 2035 | AE6: 2040 | AF6: 2025 | AG6: 2030 | AH6: 2035 | AI6: 2040 | AJ6: 2025 | AK6: 2030 | AL6: 2035 | AM6: 2040 | AN6: 2025 | AO6: 2030 | AP6: 2035 | AQ6: 2040 | AR6: 2025 | AS6: 2030 | AT6: 2035 | AU6: 2040 | AV6: 2025 | AW6: 2030 | AX6: 2035 | AY6: 2040 | AZ6: 2025 | BA6: 2030 | BB6: 2035 | BC6: 2040 | BD6: 2025 | BE6: 2030 | BF6: 2035 | BG6: 2040 | BH6: 2025 | BI6: 2030 | BJ6: 2035 | BK6: 2040 | BL6: 2025 | BM6: 2030 | BN6: 2035 | BO6: 2040 | BP6: 2025 | BQ6: 2030 | BR6: 2035 | BS6: 2040 | BT6: 2025 | BU6: 2030 | BV6: 2035 | BW6: 2040 | BX6: 2025 | BY6: 2030 | BZ6: 2035 | CA6: 2040 | CB6: 2025 | CC6: 2030 | CD6: 2035 | CE6: 2040 | CF6: 2025 | CG6: 2030 | CH6: 2035 | CI6: 2040 | CJ6: 2025 | CK6: 2030 | CL6: 2035 | CM6: 2040 | CN6: 2020 | CO6: 2020 | CP6: 2020 | CQ6: 2025 | CR6: 2030 | CS6: 2035 | CT6: 2040 | CU6: 2025 | CV6: 2030 | CW6: 2035 | CX6: 2040 | CY6: 2025 | CZ6: 2030 | DA6: 2035 | DB6: 2040 | DC6: 2025 | DD6: 2030 | DE6: 2035 | DF6: 2040 | DG6: 2025 | DH6: 2030 | DI6: 2035 | DJ6: 2040 | DK6: 2025 | DL6: 2030 | DM6: 2035 | DN6: 2040 | DO6: 2025 | DP6: 2030 | DQ6: 2035 | DR6: 2040 | DS6: 2025 | DT6: 2030 | DU6: 2035 | DV6: 2040 | DW6: 2025 | DX6: 2030 | DY6: 2035 | DZ6: 2040 | EA6: 2025 | EB6: 2030 | EC6: 2035 | ED6: 2040 | EE6: 2025 | EF6: 2030 | EG6: 2035 | EH6: 2040 | EI6: 2025 | EJ6: 2030 | EK6: 2035 | EL6: 2040 | EM6: 2025 | EN6: 2030 | EO6: 2035 | EP6: 2040 | EQ6: 2025 | ER6: 2030 | ES6: 2035 | ET6: 2040 | EU6: 2025 | EV6: 2030 | EW6: 2035 | EX6: 2040 | EY6: 2025 | EZ6: 2030 | FA6: 2035 | FB6: 2040 | FC6: 2025 | FD6: 2030 | FE6: 2035 | FF6: 2040 | FG6: 2025 | FH6: 2030 | FI6: 2035 | FJ6: 2040 | FK6: 2030 | FL6: 2020 | FM6: 2020 | FN6: 2020 | FO6: 2035
A7: Koodi | D7: CCGT H Class, 2025, UK | E7: CCGT H Class, 2030, UK | F7: CCGT H Class, 2035, UK | G7: CCGT H Class, 2040, UK | H7: CCGT CHP mode, 2025, UK | I7: CCGT CHP mode, 2030, UK | J7: CCGT CHP mode, 2035, UK | K7: CCGT CHP mode, 2040, UK | L7: OCGT 600MW 500 hr, 2025, UK | M7: OCGT 600MW 500 hr, 2030, UK | N7: OCGT 600MW 500 hr, 2035, UK | O7: OCGT 600MW 500 hr, 2040, UK | P7: OCGT 400MW 500 hr, 2025, UK | Q7: OCGT 400MW 500 hr, 2030, UK | R7: OCGT 400MW 500 hr, 2035, UK | S7: OCGT 400MW 500 hr, 2040, UK | T7: OCGT 300MW 500 hr, 2025, UK | U7: OCGT 300MW 500 hr, 2030, UK | V7: OCGT 300MW 500 hr, 2035, UK | W7: OCGT 300MW 500 hr, 2040, UK | X7: OCGT 299MW 500 hr, 2025, UK | Y7: OCGT 299MW 500 hr, 2030, UK | Z7: OCGT 299MW 500 hr, 2035, UK | AA7: OCGT 299MW 500 hr, 2040, UK | AB7: OCGT 100MW 500 hr, 2025, UK | AC7: OCGT 100MW 500 hr, 2030, UK | AD7: OCGT 100MW 500 hr, 2035, UK | AE7: OCGT 100MW 500 hr, 2040, UK | AF7: OCGT 600MW 2000 hr, 2025, UK | AG7: OCGT 600MW 2000 hr, 2030, UK | AH7: OCGT 600MW 2000 hr, 2035, UK | AI7: OCGT 600MW 2000 hr, 2040, UK | AJ7: OCGT 400MW 2000 hr, 2025, UK | AK7: OCGT 400MW 2000 hr, 2030, UK | AL7: OCGT 400MW 2000 hr, 2035, UK | AM7: OCGT 400MW 2000 hr, 2040, UK | AN7: OCGT 300MW 2000 hr, 2025, UK | AO7: OCGT 300MW 2000 hr, 2030, UK | AP7: OCGT 300MW 2000 hr, 2035, UK | AQ7: OCGT 300MW 2000 hr, 2040, UK | AR7: OCGT 299MW 2000 hr, 2025, UK | AS7: OCGT 299MW 2000 hr, 2030, UK | AT7: OCGT 299MW 2000 hr, 2035, UK | AU7: OCGT 299MW 2000 hr, 2040, UK | AV7: OCGT 100MW 2000 hr, 2025, UK | AW7: OCGT 100MW 2000 hr, 2030, UK | AX7: OCGT 100MW 2000 hr, 2035, UK | AY7: OCGT 100MW 2000 hr, 2040, UK | AZ7: Recip Diesel 2000 hr, 2025, UK | BA7: Recip Diesel 2000 hr, 2030, UK | BB7: Recip Diesel 2000 hr, 2035, UK | BC7: Recip Diesel 2000 hr, 2040, UK | BD7: Recip Diesel 500 hrs, 2025, UK | BE7: Recip Diesel 500 hrs, 2030, UK | BF7: Recip Diesel 500 hrs, 2035, UK | BG7: Recip Diesel 500 hrs, 2040, UK | BH7: Recip Diesel 90 hrs, 2025, UK | BI7: Recip Diesel 90 hrs, 2030, UK | BJ7: Recip Diesel 90 hrs, 2035, UK | BK7: Recip Diesel 90 hrs, 2040, UK | BL7: Recip Gas 2000 hr, 2025, UK | BM7: Recip Gas 2000 hr, 2030, UK | BN7: Recip Gas 2000 hr, 2035, UK | BO7: Recip Gas 2000 hr, 2040, UK | BP7: Recip Gas 500 hrs, 2025, UK | BQ7: Recip Gas 500 hrs, 2030, UK | BR7: Recip Gas 500 hrs, 2035, UK | BS7: Recip Gas 500 hrs, 2040, UK | BT7: Dedicated Biomass, 2025, UK | BU7: Dedicated Biomass, 2030, UK | BV7: Dedicated Biomass, 2035, UK | BW7: Dedicated Biomass, 2040, UK | BX7: Biomass CHP, 2025, UK | BY7: Biomass CHP, 2030, UK | BZ7: Biomass CHP, 2035, UK | CA7: Biomass CHP, 2040, UK | CB7: Onshore Wind, 2025, UK | CC7: Onshore Wind, 2030, UK | CD7: Onshore Wind, 2035, UK | CE7: Onshore Wind, 2040, UK | CF7: Offshore Wind, 2025, UK | CG7: Offshore Wind, 2030, UK | CH7: Offshore Wind, 2035, UK | CI7: Offshore Wind, 2040, UK | CJ7: Large-scale Solar, 2025, UK | CK7: Large-scale Solar, 2030, UK | CL7: Large-scale Solar, 2035, UK | CM7: Large-scale Solar, 2040, UK | CN7: Teollinen aurinkosähkö, lattiahinta 1998 ja 2000 (Way2022b) | CO7: Teollinen aurinkosähkö, lattiahinta 2005 (Way2022b) | CP7: Teollinen aurinkosähkö, lattiahinta 2015 (Way2022b) | CQ7: Solar PV 10-50kW, 2025, UK | CR7: Solar PV 10-50kW, 2030, UK | CS7: Solar PV 10-50kW, 2035, UK | CT7: Solar PV 10-50kW, 2040, UK | CU7: Solar PV 4-10kW, 2025, UK | CV7: Solar PV 4-10kW, 2030, UK | CW7: Solar PV 4-10kW, 2035, UK | CX7: Solar PV 4-10kW, 2040, UK | CY7: Solar PV <4kW, 2025, UK | CZ7: Solar PV <4kW, 2030, UK | DA7: Solar PV <4kW, 2035, UK | DB7: Solar PV <4kW, 2040, UK | DC7: EfW, 2025, UK | DD7: EfW, 2030, UK | DE7: EfW, 2035, UK | DF7: EfW, 2040, UK | DG7: EfW CHP, 2025, UK | DH7: EfW CHP, 2030, UK | DI7: EfW CHP, 2035, UK | DJ7: EfW CHP, 2040, UK | DK7: AD, 2025, UK | DL7: AD, 2030, UK | DM7: AD, 2035, UK | DN7: AD, 2040, UK | DO7: AD CHP, 2025, UK | DP7: AD CHP, 2030, UK | DQ7: AD CHP, 2035, UK | DR7: AD CHP, 2040, UK | DS7: ACT Standard, 2025, UK | DT7: ACT Standard, 2030, UK | DU7: ACT Standard, 2035, UK | DV7: ACT Standard, 2040, UK | DW7: ACT Advanced, 2025, UK | DX7: ACT Advanced, 2030, UK | DY7: ACT Advanced, 2035, UK | DZ7: ACT Advanced, 2040, UK | EA7: ACT CHP, 2025, UK | EB7: ACT CHP, 2030, UK | EC7: ACT CHP, 2035, UK | ED7: ACT CHP, 2040, UK | EE7: Landfill gas, 2025, UK | EF7: Landfill gas, 2030, UK | EG7: Landfill gas, 2035, UK | EH7: Landfill gas, 2040, UK | EI7: Sewage gas, 2025, UK | EJ7: Sewage gas, 2030, UK | EK7: Sewage gas, 2035, UK | EL7: Sewage gas, 2040, UK | EM7: Geothermal CHP, 2025, UK | EN7: Geothermal CHP, 2030, UK | EO7: Geothermal CHP, 2035, UK | EP7: Geothermal CHP, 2040, UK | EQ7: Hydro Large Storage, 2025, UK | ER7: Hydro Large Storage, 2030, UK | ES7: Hydro Large Storage, 2035, UK | ET7: Hydro Large Storage, 2040, UK | EU7: Hydro 516MW, 2025, UK | EV7: Hydro 516MW, 2030, UK | EW7: Hydro 516MW, 2035, UK | EX7: Hydro 516MW, 2040, UK | EY7: Wave, 2025, UK | EZ7: Wave, 2030, UK | FA7: Wave, 2035, UK | FB7: Wave, 2040, UK | FC7: Hydrogen CCGT (FOAK), 2025, UK | FD7: Hydrogen CCGT (FOAK), 2030, UK | FE7: Hydrogen CCGT (FOAK), 2035, UK | FF7: Hydrogen CCGT (FOAK), 2040, UK | FG7: Hydrogen CCGT (NOAK), 2025, UK | FH7: Hydrogen CCGT (NOAK), 2030, UK | FI7: Hydrogen CCGT (NOAK), 2035, UK | FJ7: Hydrogen CCGT (NOAK), 2040, UK | FK7: AP1000-reaktori, Puola | FL7: EPR-reaktori, Suomi | FM7: Tuulivoima, Suomi, 2017 | FN7: Kaasuvoima, Suomi, 2017 | FO7: Ydinreaktori, 1 250 MW, Ruotsi 2024 referenssilaskelma
A8: Case | D8: 1 | E8: 2 | F8: 3 | G8: 4 | H8: 5 | I8: 6 | J8: 7 | K8: 8 | L8: 9 | M8: 10 | N8: 11 | O8: 12 | P8: 13 | Q8: 14 | R8: 15 | S8: 16 | T8: 17 | U8: 18 | V8: 19 | W8: 20 | X8: 21 | Y8: 22 | Z8: 23 | AA8: 24 | AB8: 25 | AC8: 26 | AD8: 27 | AE8: 28 | AF8: 29 | AG8: 30 | AH8: 31 | AI8: 32 | AJ8: 33 | AK8: 34 | AL8: 35 | AM8: 36 | AN8: 37 | AO8: 38 | AP8: 39 | AQ8: 40 | AR8: 41 | AS8: 42 | AT8: 43 | AU8: 44 | AV8: 45 | AW8: 46 | AX8: 47 | AY8: 48 | AZ8: 49 | BA8: 50 | BB8: 51 | BC8: 52 | BD8: 53 | BE8: 54 | BF8: 55 | BG8: 56 | BH8: 57 | BI8: 58 | BJ8: 59 | BK8: 60 | BL8: 61 | BM8: 62 | BN8: 63 | BO8: 64 | BP8: 65 | BQ8: 66 | BR8: 67 | BS8: 68 | BT8: 69 | BU8: 70 | BV8: 71 | BW8: 72 | BX8: 73 | BY8: 74 | BZ8: 75 | CA8: 76 | CB8: 77 | CC8: 78 | CD8: 79 | CE8: 80 | CF8: 81 | CG8: 82 | CH8: 83 | CI8: 84 | CJ8: 85 | CK8: 86 | CL8: 87 | CM8: 88 | CQ8: 89 | CR8: 90 | CS8: 91 | CT8: 92 | CU8: 93 | CV8: 94 | CW8: 95 | CX8: 96 | CY8: 97 | CZ8: 98 | DA8: 99 | DB8: 100 | DC8: 101 | DD8: 102 | DE8: 103 | DF8: 104 | DG8: 105 | DH8: 106 | DI8: 107 | DJ8: 108 | DK8: 109 | DL8: 110 | DM8: 111 | DN8: 112 | DO8: 113 | DP8: 114 | DQ8: 115 | DR8: 116 | DS8: 117 | DT8: 118 | DU8: 119 | DV8: 120 | DW8: 121 | DX8: 122 | DY8: 123 | DZ8: 124 | EA8: 125 | EB8: 126 | EC8: 127 | ED8: 128 | EE8: 129 | EF8: 130 | EG8: 131 | EH8: 132 | EI8: 133 | EJ8: 134 | EK8: 135 | EL8: 136 | EM8: 137 | EN8: 138 | EO8: 139 | EP8: 140 | EQ8: 141 | ER8: 142 | ES8: 143 | ET8: 144 | EU8: 145 | EV8: 146 | EW8: 147 | EX8: 148 | EY8: 149 | EZ8: 150 | FA8: 151 | FB8: 152 | FC8: 153 | FD8: 154 | FE8: 155 | FF8: 156 | FG8: 157 | FH8: 158 | FI8: 159 | FJ8: 160 | FK8: 161 | FL8: 162 | FM8: 163 | FN8: 164 | FO8: 165
A9: Polttoaine | D9: Maakaasu | E9: Maakaasu | F9: Maakaasu | G9: Maakaasu | H9: Maakaasu | I9: Maakaasu | J9: Maakaasu | K9: Maakaasu | L9: Maakaasu | M9: Maakaasu | N9: Maakaasu | O9: Maakaasu | P9: Maakaasu | Q9: Maakaasu | R9: Maakaasu | S9: Maakaasu | T9: Maakaasu | U9: Maakaasu | V9: Maakaasu | W9: Maakaasu | X9: Maakaasu | Y9: Maakaasu | Z9: Maakaasu | AA9: Maakaasu | AB9: Maakaasu | AC9: Maakaasu | AD9: Maakaasu | AE9: Maakaasu | AF9: Maakaasu | AG9: Maakaasu | AH9: Maakaasu | AI9: Maakaasu | AJ9: Maakaasu | AK9: Maakaasu | AL9: Maakaasu | AM9: Maakaasu | AN9: Maakaasu | AO9: Maakaasu | AP9: Maakaasu | AQ9: Maakaasu | AR9: Maakaasu | AS9: Maakaasu | AT9: Maakaasu | AU9: Maakaasu | AV9: Maakaasu | AW9: Maakaasu | AX9: Maakaasu | AY9: Maakaasu | AZ9: Diesel | BA9: Diesel | BB9: Diesel | BC9: Diesel | BD9: Diesel | BE9: Diesel | BF9: Diesel | BG9: Diesel | BH9: Diesel | BI9: Diesel | BJ9: Diesel | BK9: Diesel | BL9: Maakaasu | BM9: Maakaasu | BN9: Maakaasu | BO9: Maakaasu | BP9: Maakaasu | BQ9: Maakaasu | BR9: Maakaasu | BS9: Maakaasu | BT9: Biomassa | BU9: Biomassa | BV9: Biomassa | BW9: Biomassa | BX9: Biomassa | BY9: Biomassa | BZ9: Biomassa | CA9: Biomassa | CB9: Tuuli | CC9: Tuuli | CD9: Tuuli | CE9: Tuuli | CF9: Tuuli | CG9: Tuuli | CH9: Tuuli | CI9: Tuuli | CJ9: Aurinko | CK9: Aurinko | CL9: Aurinko | CM9: Aurinko | CN9: Aurinko | CO9: Aurinko | CP9: Aurinko | CQ9: Aurinko | CR9: Aurinko | CS9: Aurinko | CT9: Aurinko | CU9: Aurinko | CV9: Aurinko | CW9: Aurinko | CX9: Aurinko | CY9: Aurinko | CZ9: Aurinko | DA9: Aurinko | DB9: Aurinko | DC9: Jäte | DD9: Jäte | DE9: Jäte | DF9: Jäte | DG9: Jäte | DH9: Jäte | DI9: Jäte | DJ9: Jäte | EM9: Geoterminen | EN9: Geoterminen | EO9: Geoterminen | EP9: Geoterminen | EQ9: Vesi | ER9: Vesi | ES9: Vesi | ET9: Vesi | EU9: Vesi | EV9: Vesi | EW9: Vesi | EX9: Vesi | EY9: Vesi | EZ9: Vesi | FA9: Vesi | FB9: Vesi | FC9: Vety | FD9: Vety | FE9: Vety | FF9: Vety | FG9: Vety | FH9: Vety | FI9: Vety | FJ9: Vety | FK9: Uraani | FL9: Uraani | FM9: Tuuli | FN9: Maakaasu | FO9: Uraani
FO10: Kyllä
A11: Huom1 | D11: N/A | E11: N/A | F11: N/A | G11: N/A | H11: N/A | I11: N/A | J11: N/A | K11: N/A | L11: N/A | M11: N/A | N11: N/A | O11: N/A | P11: N/A | Q11: N/A | R11: N/A | S11: N/A | T11: N/A | U11: N/A | V11: N/A | W11: N/A | X11: N/A | Y11: N/A | Z11: N/A | AA11: N/A | AB11: N/A | AC11: N/A | AD11: N/A | AE11: N/A | AF11: N/A | AG11: N/A | AH11: N/A | AI11: N/A | AJ11: N/A | AK11: N/A | AL11: N/A | AM11: N/A | AN11: N/A | AO11: N/A | AP11: N/A | AQ11: N/A | AR11: N/A | AS11: N/A | AT11: N/A | AU11: N/A | AV11: N/A | AW11: N/A | AX11: N/A | AY11: N/A | AZ11: N/A | BA11: N/A | BB11: N/A | BC11: N/A | BD11: N/A | BE11: N/A | BF11: N/A | BG11: N/A | BH11: N/A | BI11: N/A | BJ11: N/A | BK11: N/A | BL11: N/A | BM11: N/A | BN11: N/A | BO11: N/A | BP11: N/A | BQ11: N/A | BR11: N/A | BS11: N/A | BT11: N/A | BU11: N/A | BV11: N/A | BW11: N/A | BX11: N/A | BY11: N/A | BZ11: N/A | CA11: N/A | CB11: N/A | CC11: N/A | CD11: N/A | CE11: N/A | CF11: N/A | CG11: N/A | CH11: N/A | CI11: N/A | CJ11: N/A | CK11: N/A | CL11: N/A | CM11: N/A | CN11: Lattiahinta lähteen Way2022b:99 perusteella ERIS (1998), MERGE-ETL ja TIMES-G5 malleista, muut tiedot Iso-Britannian Large-scale solar 2025 | CO11: Lattiahinta 2005 lähteen Way2022b:99 perusteella ReMIND-R, POLES, ja WITCH-malleista, muut tiedot Iso-Britannian Large-scale solar 2025 | CP11: Lattiahinta 2015 lähteen Way2022b:99 perusteella REMIND- ja POLES-malleista, muut tiedot Iso-Britannian Large-scale solar 2025 | CQ11: N/A | CR11: N/A | CS11: N/A | CT11: N/A | CU11: N/A | CV11: N/A | CW11: N/A | CX11: N/A | CY11: N/A | CZ11: N/A | DA11: N/A | DB11: N/A | DC11: N/A | DD11: N/A | DE11: N/A | DF11: N/A | DG11: N/A | DH11: N/A | DI11: N/A | DJ11: N/A | DK11: N/A | DL11: N/A | DM11: N/A | DN11: N/A | DO11: N/A | DP11: N/A | DQ11: N/A | DR11: N/A | DS11: N/A | DT11: N/A | DU11: N/A | DV11: N/A | DW11: N/A | DX11: N/A | DY11: N/A | DZ11: N/A | EA11: N/A | EB11: N/A | EC11: N/A | ED11: N/A | EE11: N/A | EF11: N/A | EG11: N/A | EH11: N/A | EI11: N/A | EJ11: N/A | EK11: N/A | EL11: N/A | EM11: N/A | EN11: N/A | EO11: N/A | EP11: N/A | EQ11: N/A | ER11: N/A | ES11: N/A | ET11: N/A | EU11: N/A | EV11: N/A | EW11: N/A | EX11: N/A | EY11: N/A | EZ11: N/A | FA11: N/A | FB11: N/A | FC11: N/A | FD11: N/A | FE11: N/A | FF11: N/A | FG11: N/A | FH11: N/A | FI11: N/A | FJ11: N/A | FK11: Westinghouse winning bid for 3+3 reactors in Poland, 2022 | FL11: Lähteestä Vakkilainen2017 | FM11: Lähteestä Vakkilainen2017 | FN11: Lähteestä Vakkilainen2017 | FO11: Ruotsin hallituksen selvityksestä
